Workbook

Sheet Datos Ventas
A1: =IFERROR(__xludf.DUMMYFUNCTION("importdata(""https://drive.google.com/uc?export=download&id=1U1AR8u12BH41vb1Uvb31WaPc4KTs4qQo&v=2"","";"")"),"Empresa") -> Empresa | B1: =IFERROR(__xludf.DUMMYFUNCTION("""COMPUTED_VALUE"""),"Número de Documento") -> Número de Documento | C1: =IFERROR(__xludf.DUMMYFUNCTION("""COMPUTED_VALUE"""),"Año Fiscal") -> Año Fiscal | D1: =IFERROR(__xludf.DUMMYFUNCTION("""COMPUTED_VALUE"""),"Fecha") -> Fecha | E1: =IFERROR(__xludf.DUMMYFUNCTION("""COMPUTED_VALUE"""),"Tipo de Documento") -> Tipo de Documento | F1: =IFERROR(__xludf.DUMMYFUNCTION("""COMPUTED_VALUE"""),"Número de Artículo") -> Número de Artículo | G1: =IFERROR(__xludf.DUMMYFUNCTION("""COMPUTED_VALUE"""),"Material") -> Material | H1: =IFERROR(__xludf.DUMMYFUNCTION("""COMPUTED_VALUE"""),"Vendedor") -> Vendedor | I1: =IFERROR(__xludf.DUMMYFUNCTION("""COMPUTED_VALUE"""),"Cantidad") -> Cantidad | J1: =IFERROR(__xludf.DUMMYFUNCTION("""COMPUTED_VALUE"""),"Valor en Moneda Local") -> Valor en Moneda Local | K1: =IFERROR(__xludf.DUMMYFUNCTION("""COMPUTED_VALUE"""),"Valor en Moneda Extranjera") -> Valor en Moneda Extranjera
A2: =IFERROR(__xludf.DUMMYFUNCTION("""COMPUTED_VALUE"""),1000.0) -> 1000 | B2: =IFERROR(__xludf.DUMMYFUNCTION("""COMPUTED_VALUE"""),183456.0) -> 183456 | C2: =IFERROR(__xludf.DUMMYFUNCTION("""COMPUTED_VALUE"""),2026.0) -> 2026 | D2: =IFERROR(__xludf.DUMMYFUNCTION("""COMPUTED_VALUE"""),46387.0) -> 46387 | E2: =IFERROR(__xludf.DUMMYFUNCTION("""COMPUTED_VALUE"""),"VF") -> VF | F2: =IFERROR(__xludf.DUMMYFUNCTION("""COMPUTED_VALUE"""),1.0) -> 1 | G2: =IFERROR(__xludf.DUMMYFUNCTION("""COMPUTED_VALUE"""),"PR001") -> PR001 | H2: =IFERROR(__xludf.DUMMYFUNCTION("""COMPUTED_VALUE"""),"VD026") -> VD026 | I2: =IFERROR(__xludf.DUMMYFUNCTION("""COMPUTED_VALUE"""),27.0) -> 27 | J2: =IFERROR(__xludf.DUMMYFUNCTION("""COMPUTED_VALUE"""),1957.23) -> 1957.23 | K2: =IFERROR(__xludf.DUMMYFUNCTION("""COMPUTED_VALUE"""),1957.23) -> 1957.23
A3: =IFERROR(__xludf.DUMMYFUNCTION("""COMPUTED_VALUE"""),1000.0) -> 1000 | B3: =IFERROR(__xludf.DUMMYFUNCTION("""COMPUTED_VALUE"""),183456.0) -> 183456 | C3: =IFERROR(__xludf.DUMMYFUNCTION("""COMPUTED_VALUE"""),2026.0) -> 2026 | D3: =IFERROR(__xludf.DUMMYFUNCTION("""COMPUTED_VALUE"""),46387.0) -> 46387 | E3: =IFERROR(__xludf.DUMMYFUNCTION("""COMPUTED_VALUE"""),"VF") -> VF | F3: =IFERROR(__xludf.DUMMYFUNCTION("""COMPUTED_VALUE"""),2.0) -> 2 | G3: =IFERROR(__xludf.DUMMYFUNCTION("""COMPUTED_VALUE"""),"PR058") -> PR058 | H3: =IFERROR(__xludf.DUMMYFUNCTION("""COMPUTED_VALUE"""),"VD037") -> VD037 | I3: =IFERROR(__xludf.DUMMYFUNCTION("""COMPUTED_VALUE"""),14.0) -> 14 | J3: =IFERROR(__xludf.DUMMYFUNCTION("""COMPUTED_VALUE"""),2872.8) -> 2872.8 | K3: =IFERROR(__xludf.DUMMYFUNCTION("""COMPUTED_VALUE"""),2872.8) -> 2872.8
A4: =IFERROR(__xludf.DUMMYFUNCTION("""COMPUTED_VALUE"""),1000.0) -> 1000 | B4: =IFERROR(__xludf.DUMMYFUNCTION("""COMPUTED_VALUE"""),183457.0) -> 183457 | C4: =IFERROR(__xludf.DUMMYFUNCTION("""COMPUTED_VALUE"""),2026.0) -> 2026 | D4: =IFERROR(__xludf.DUMMYFUNCTION("""COMPUTED_VALUE"""),46387.0) -> 46387 | E4: =IFERROR(__xludf.DUMMYFUNCTION("""COMPUTED_VALUE"""),"VF") -> VF | F4: =IFERROR(__xludf.DUMMYFUNCTION("""COMPUTED_VALUE"""),1.0) -> 1 | G4: =IFERROR(__xludf.DUMMYFUNCTION("""COMPUTED_VALUE"""),"PR020") -> PR020 | H4: =IFERROR(__xludf.DUMMYFUNCTION("""COMPUTED_VALUE"""),"VD034") -> VD034 | I4: =IFERROR(__xludf.DUMMYFUNCTION("""COMPUTED_VALUE"""),20.0) -> 20 | J4: =IFERROR(__xludf.DUMMYFUNCTION("""COMPUTED_VALUE"""),7137.62) -> 7137.62 | K4: =IFERROR(__xludf.DUMMYFUNCTION("""COMPUTED_VALUE"""),7137.62) -> 7137.62
A5: =IFERROR(__xludf.DUMMYFUNCTION("""COMPUTED_VALUE"""),1000.0) -> 1000 | B5: =IFERROR(__xludf.DUMMYFUNCTION("""COMPUTED_VALUE"""),183458.0) -> 183458 | C5: =IFERROR(__xludf.DUMMYFUNCTION("""COMPUTED_VALUE"""),2026.0) -> 2026 | D5: =IFERROR(__xludf.DUMMYFUNCTION("""COMPUTED_VALUE"""),46387.0) -> 46387 | E5: =IFERROR(__xludf.DUMMYFUNCTION("""COMPUTED_VALUE"""),"VF") -> VF | F5: =IFERROR(__xludf.DUMMYFUNCTION("""COMPUTED_VALUE"""),1.0) -> 1 | G5: =IFERROR(__xludf.DUMMYFUNCTION("""COMPUTED_VALUE"""),"PR035") -> PR035 | H5: =IFERROR(__xludf.DUMMYFUNCTION("""COMPUTED_VALUE"""),"VD021") -> VD021 | I5: =IFERROR(__xludf.DUMMYFUNCTION("""COMPUTED_VALUE"""),24.0) -> 24 | J5: =IFERROR(__xludf.DUMMYFUNCTION("""COMPUTED_VALUE"""),2478.77) -> 2478.77 | K5: =IFERROR(__xludf.DUMMYFUNCTION("""COMPUTED_VALUE"""),2478.77) -> 2478.77
A6: =IFERROR(__xludf.DUMMYFUNCTION("""COMPUTED_VALUE"""),1000.0) -> 1000 | B6: =IFERROR(__xludf.DUMMYFUNCTION("""COMPUTED_VALUE"""),183459.0) -> 183459 | C6: =IFERROR(__xludf.DUMMYFUNCTION("""COMPUTED_VALUE"""),2026.0) -> 2026 | D6: =IFERROR(__xludf.DUMMYFUNCTION("""COMPUTED_VALUE"""),46387.0) -> 46387 | E6: =IFERROR(__xludf.DUMMYFUNCTION("""COMPUTED_VALUE"""),"VF") -> VF | F6: =IFERROR(__xludf.DUMMYFUNCTION("""COMPUTED_VALUE"""),1.0) -> 1 | G6: =IFERROR(__xludf.DUMMYFUNCTION("""COMPUTED_VALUE"""),"PR016") -> PR016 | H6: =IFERROR(__xludf.DUMMYFUNCTION("""COMPUTED_VALUE"""),"VD027") -> VD027 | I6: =IFERROR(__xludf.DUMMYFUNCTION("""COMPUTED_VALUE"""),10.0) -> 10 | J6: =IFERROR(__xludf.DUMMYFUNCTION("""COMPUTED_VALUE"""),303.03) -> 303.03 | K6: =IFERROR(__xludf.DUMMYFUNCTION("""COMPUTED_VALUE"""),303.03) -> 303.03
A7: =IFERROR(__xludf.DUMMYFUNCTION("""COMPUTED_VALUE"""),1000.0) -> 1000 | B7: =IFERROR(__xludf.DUMMYFUNCTION("""COMPUTED_VALUE"""),183460.0) -> 183460 | C7: =IFERROR(__xludf.DUMMYFUNCTION("""COMPUTED_VALUE"""),2026.0) -> 2026 | D7: =IFERROR(__xludf.DUMMYFUNCTION("""COMPUTED_VALUE"""),46387.0) -> 46387 | E7: =IFERROR(__xludf.DUMMYFUNCTION("""COMPUTED_VALUE"""),"VF") -> VF | F7: =IFERROR(__xludf.DUMMYFUNCTION("""COMPUTED_VALUE"""),1.0) -> 1 | G7: =IFERROR(__xludf.DUMMYFUNCTION("""COMPUTED_VALUE"""),"PR051") -> PR051 | H7: =IFERROR(__xludf.DUMMYFUNCTION("""COMPUTED_VALUE"""),"VD048") -> VD048 | I7: =IFERROR(__xludf.DUMMYFUNCTION("""COMPUTED_VALUE"""),18.0) -> 18 | J7: =IFERROR(__xludf.DUMMYFUNCTION("""COMPUTED_VALUE"""),704.72) -> 704.72 | K7: =IFERROR(__xludf.DUMMYFUNCTION("""COMPUTED_VALUE"""),704.72) -> 704.72
A8: =IFERROR(__xludf.DUMMYFUNCTION("""COMPUTED_VALUE"""),1000.0) -> 1000 | B8: =IFERROR(__xludf.DUMMYFUNCTION("""COMPUTED_VALUE"""),183461.0) -> 183461 | C8: =IFERROR(__xludf.DUMMYFUNCTION("""COMPUTED_VALUE"""),2026.0) -> 2026 | D8: =IFERROR(__xludf.DUMMYFUNCTION("""COMPUTED_VALUE"""),46387.0) -> 46387 | E8: =IFERROR(__xludf.DUMMYFUNCTION("""COMPUTED_VALUE"""),"VF") -> VF | F8: =IFERROR(__xludf.DUMMYFUNCTION("""COMPUTED_VALUE"""),1.0) -> 1 | G8: =IFERROR(__xludf.DUMMYFUNCTION("""COMPUTED_VALUE"""),"PR042") -> PR042 | H8: =IFERROR(__xludf.DUMMYFUNCTION("""COMPUTED_VALUE"""),"VD025") -> VD025 | I8: =IFERROR(__xludf.DUMMYFUNCTION("""COMPUTED_VALUE"""),27.0) -> 27 | J8: =IFERROR(__xludf.DUMMYFUNCTION("""COMPUTED_VALUE"""),1778.76) -> 1778.76 | K8: =IFERROR(__xludf.DUMMYFUNCTION("""COMPUTED_VALUE"""),1778.76) -> 1778.76
A9: =IFERROR(__xludf.DUMMYFUNCTION("""COMPUTED_VALUE"""),1000.0) -> 1000 | B9: =IFERROR(__xludf.DUMMYFUNCTION("""COMPUTED_VALUE"""),183462.0) -> 183462 | C9: =IFERROR(__xludf.DUMMYFUNCTION("""COMPUTED_VALUE"""),2026.0) -> 2026 | D9: =IFERROR(__xludf.DUMMYFUNCTION("""COMPUTED_VALUE"""),46387.0) -> 46387 | E9: =IFERROR(__xludf.DUMMYFUNCTION("""COMPUTED_VALUE"""),"VF") -> VF | F9: =IFERROR(__xludf.DUMMYFUNCTION("""COMPUTED_VALUE"""),1.0) -> 1 | G9: =IFERROR(__xludf.DUMMYFUNCTION("""COMPUTED_VALUE"""),"PR050") -> PR050 | H9: =IFERROR(__xludf.DUMMYFUNCTION("""COMPUTED_VALUE"""),"VD037") -> VD037 | I9: =IFERROR(__xludf.DUMMYFUNCTION("""COMPUTED_VALUE"""),14.0) -> 14 | J9: =IFERROR(__xludf.DUMMYFUNCTION("""COMPUTED_VALUE"""),511.27) -> 511.27 | K9: =IFERROR(__xludf.DUMMYFUNCTION("""COMPUTED_VALUE"""),511.27) -> 511.27
A10: =IFERROR(__xludf.DUMMYFUNCTION("""COMPUTED_VALUE"""),1000.0) -> 1000 | B10: =IFERROR(__xludf.DUMMYFUNCTION("""COMPUTED_VALUE"""),183463.0) -> 183463 | C10: =IFERROR(__xludf.DUMMYFUNCTION("""COMPUTED_VALUE"""),2026.0) -> 2026 | D10: =IFERROR(__xludf.DUMMYFUNCTION("""COMPUTED_VALUE"""),46387.0) -> 46387 | E10: =IFERROR(__xludf.DUMMYFUNCTION("""COMPUTED_VALUE"""),"VF") -> VF | F10: =IFERROR(__xludf.DUMMYFUNCTION("""COMPUTED_VALUE"""),1.0) -> 1 | G10: =IFERROR(__xludf.DUMMYFUNCTION("""COMPUTED_VALUE"""),"PR001") -> PR001 | H10: =IFERROR(__xludf.DUMMYFUNCTION("""COMPUTED_VALUE"""),"VD036") -> VD036 | I10: =IFERROR(__xludf.DUMMYFUNCTION("""COMPUTED_VALUE"""),12.0) -> 12 | J10: =IFERROR(__xludf.DUMMYFUNCTION("""COMPUTED_VALUE"""),901.51) -> 901.51 | K10: =IFERROR(__xludf.DUMMYFUNCTION("""COMPUTED_VALUE"""),901.51) -> 901.51
A11: =IFERROR(__xludf.DUMMYFUNCTION("""COMPUTED_VALUE"""),1000.0) -> 1000 | B11: =IFERROR(__xludf.DUMMYFUNCTION("""COMPUTED_VALUE"""),183464.0) -> 183464 | C11: =IFERROR(__xludf.DUMMYFUNCTION("""COMPUTED_VALUE"""),2026.0) -> 2026 | D11: =IFERROR(__xludf.DUMMYFUNCTION("""COMPUTED_VALUE"""),46387.0) -> 46387 | E11: =IFERROR(__xludf.DUMMYFUNCTION("""COMPUTED_VALUE"""),"VF") -> VF | F11: =IFERROR(__xludf.DUMMYFUNCTION("""COMPUTED_VALUE"""),1.0) -> 1 | G11: =IFERROR(__xludf.DUMMYFUNCTION("""COMPUTED_VALUE"""),"PR059") -> PR059 | H11: =IFERROR(__xludf.DUMMYFUNCTION("""COMPUTED_VALUE"""),"VD049") -> VD049 | I11: =IFERROR(__xludf.DUMMYFUNCTION("""COMPUTED_VALUE"""),27.0) -> 27 | J11: =IFERROR(__xludf.DUMMYFUNCTION("""COMPUTED_VALUE"""),5783.4) -> 5783.4 | K11: =IFERROR(__xludf.DUMMYFUNCTION("""COMPUTED_VALUE"""),5783.4) -> 5783.4
A12: =IFERROR(__xludf.DUMMYFUNCTION("""COMPUTED_VALUE"""),1000.0) -> 1000 | B12: =IFERROR(__xludf.DUMMYFUNCTION("""COMPUTED_VALUE"""),183465.0) -> 183465 | C12: =IFERROR(__xludf.DUMMYFUNCTION("""COMPUTED_VALUE"""),2026.0) -> 2026 | D12: =IFERROR(__xludf.DUMMYFUNCTION("""COMPUTED_VALUE"""),46387.0) -> 46387 | E12: =IFERROR(__xludf.DUMMYFUNCTION("""COMPUTED_VALUE"""),"VF") -> VF | F12: =IFERROR(__xludf.DUMMYFUNCTION("""COMPUTED_VALUE"""),1.0) -> 1 | G12: =IFERROR(__xludf.DUMMYFUNCTION("""COMPUTED_VALUE"""),"PR019") -> PR019 | H12: =IFERROR(__xludf.DUMMYFUNCTION("""COMPUTED_VALUE"""),"VD021") -> VD021 | I12: =IFERROR(__xludf.DUMMYFUNCTION("""COMPUTED_VALUE"""),15.0) -> 15 | J12: =IFERROR(__xludf.DUMMYFUNCTION("""COMPUTED_VALUE"""),845.81) -> 845.81 | K12: =IFERROR(__xludf.DUMMYFUNCTION("""COMPUTED_VALUE"""),845.81) -> 845.81
A13: =IFERROR(__xludf.DUMMYFUNCTION("""COMPUTED_VALUE"""),1000.0) -> 1000 | B13: =IFERROR(__xludf.DUMMYFUNCTION("""COMPUTED_VALUE"""),183466.0) -> 183466 | C13: =IFERROR(__xludf.DUMMYFUNCTION("""COMPUTED_VALUE"""),2026.0) -> 2026 | D13: =IFERROR(__xludf.DUMMYFUNCTION("""COMPUTED_VALUE"""),46387.0) -> 46387 | E13: =IFERROR(__xludf.DUMMYFUNCTION("""COMPUTED_VALUE"""),"VF") -> VF | F13: =IFERROR(__xludf.DUMMYFUNCTION("""COMPUTED_VALUE"""),1.0) -> 1 | G13: =IFERROR(__xludf.DUMMYFUNCTION("""COMPUTED_VALUE"""),"PR055") -> PR055 | H13: =IFERROR(__xludf.DUMMYFUNCTION("""COMPUTED_VALUE"""),"VD015") -> VD015 | I13: =IFERROR(__xludf.DUMMYFUNCTION("""COMPUTED_VALUE"""),18.0) -> 18 | J13: =IFERROR(__xludf.DUMMYFUNCTION("""COMPUTED_VALUE"""),1844.75) -> 1844.75 | K13: =IFERROR(__xludf.DUMMYFUNCTION("""COMPUTED_VALUE"""),1844.75) -> 1844.75
A14: =IFERROR(__xludf.DUMMYFUNCTION("""COMPUTED_VALUE"""),1000.0) -> 1000 | B14: =IFERROR(__xludf.DUMMYFUNCTION("""COMPUTED_VALUE"""),183466.0) -> 183466 | C14: =IFERROR(__xludf.DUMMYFUNCTION("""COMPUTED_VALUE"""),2026.0) -> 2026 | D14: =IFERROR(__xludf.DUMMYFUNCTION("""COMPUTED_VALUE"""),46387.0) -> 46387 | E14: =IFERROR(__xludf.DUMMYFUNCTION("""COMPUTED_VALUE"""),"VF") -> VF | F14: =IFERROR(__xludf.DUMMYFUNCTION("""COMPUTED_VALUE"""),2.0) -> 2 | G14: =IFERROR(__xludf.DUMMYFUNCTION("""COMPUTED_VALUE"""),"PR052") -> PR052 | H14: =IFERROR(__xludf.DUMMYFUNCTION("""COMPUTED_VALUE"""),"VD012") -> VD012 | I14: =IFERROR(__xludf.DUMMYFUNCTION("""COMPUTED_VALUE"""),16.0) -> 16 | J14: =IFERROR(__xludf.DUMMYFUNCTION("""COMPUTED_VALUE"""),950.1) -> 950.1 | K14: =IFERROR(__xludf.DUMMYFUNCTION("""COMPUTED_VALUE"""),950.1) -> 950.1
A15: =IFERROR(__xludf.DUMMYFUNCTION("""COMPUTED_VALUE"""),1000.0) -> 1000 | B15: =IFERROR(__xludf.DUMMYFUNCTION("""COMPUTED_VALUE"""),183466.0) -> 183466 | C15: =IFERROR(__xludf.DUMMYFUNCTION("""COMPUTED_VALUE"""),2026.0) -> 2026 | D15: =IFERROR(__xludf.DUMMYFUNCTION("""COMPUTED_VALUE"""),46387.0) -> 46387 | E15: =IFERROR(__xludf.DUMMYFUNCTION("""COMPUTED_VALUE"""),"VF") -> VF | F15: =IFERROR(__xludf.DUMMYFUNCTION("""COMPUTED_VALUE"""),3.0) -> 3 | G15: =IFERROR(__xludf.DUMMYFUNCTION("""COMPUTED_VALUE"""),"PR052") -> PR052 | H15: =IFERROR(__xludf.DUMMYFUNCTION("""COMPUTED_VALUE"""),"VD043") -> VD043 | I15: =IFERROR(__xludf.DUMMYFUNCTION("""COMPUTED_VALUE"""),9.0) -> 9 | J15: =IFERROR(__xludf.DUMMYFUNCTION("""COMPUTED_VALUE"""),511.97) -> 511.97 | K15: =IFERROR(__xludf.DUMMYFUNCTION("""COMPUTED_VALUE"""),511.97) -> 511.97
A16: =IFERROR(__xludf.DUMMYFUNCTION("""COMPUTED_VALUE"""),1000.0) -> 1000 | B16: =IFERROR(__xludf.DUMMYFUNCTION("""COMPUTED_VALUE"""),183467.0) -> 183467 | C16: =IFERROR(__xludf.DUMMYFUNCTION("""COMPUTED_VALUE"""),2026.0) -> 2026 | D16: =IFERROR(__xludf.DUMMYFUNCTION("""COMPUTED_VALUE"""),46386.0) -> 46386 | E16: =IFERROR(__xludf.DUMMYFUNCTION("""COMPUTED_VALUE"""),"VF") -> VF | F16: =IFERROR(__xludf.DUMMYFUNCTION("""COMPUTED_VALUE"""),1.0) -> 1 | G16: =IFERROR(__xludf.DUMMYFUNCTION("""COMPUTED_VALUE"""),"PR014") -> PR014 | H16: =IFERROR(__xludf.DUMMYFUNCTION("""COMPUTED_VALUE"""),"VD020") -> VD020 | I16: =IFERROR(__xludf.DUMMYFUNCTION("""COMPUTED_VALUE"""),9.0) -> 9 | J16: =IFERROR(__xludf.DUMMYFUNCTION("""COMPUTED_VALUE"""),420.15) -> 420.15 | K16: =IFERROR(__xludf.DUMMYFUNCTION("""COMPUTED_VALUE"""),420.15) -> 420.15
A17: =IFERROR(__xludf.DUMMYFUNCTION("""COMPUTED_VALUE"""),1000.0) -> 1000 | B17: =IFERROR(__xludf.DUMMYFUNCTION("""COMPUTED_VALUE"""),183468.0) -> 183468 | C17: =IFERROR(__xludf.DUMMYFUNCTION("""COMPUTED_VALUE"""),2026.0) -> 2026 | D17: =IFERROR(__xludf.DUMMYFUNCTION("""COMPUTED_VALUE"""),46386.0) -> 46386 | E17: =IFERROR(__xludf.DUMMYFUNCTION("""COMPUTED_VALUE"""),"VF") -> VF | F17: =IFERROR(__xludf.DUMMYFUNCTION("""COMPUTED_VALUE"""),1.0) -> 1 | G17: =IFERROR(__xludf.DUMMYFUNCTION("""COMPUTED_VALUE"""),"PR055") -> PR055 | H17: =IFERROR(__xludf.DUMMYFUNCTION("""COMPUTED_VALUE"""),"VD019") -> VD019 | I17: =IFERROR(__xludf.DUMMYFUNCTION("""COMPUTED_VALUE"""),9.0) -> 9 | J17: =IFERROR(__xludf.DUMMYFUNCTION("""COMPUTED_VALUE"""),890.01) -> 890.01 | K17: =IFERROR(__xludf.DUMMYFUNCTION("""COMPUTED_VALUE"""),890.01) -> 890.01
A18: =IFERROR(__xludf.DUMMYFUNCTION("""COMPUTED_VALUE"""),1000.0) -> 1000 | B18: =IFERROR(__xludf.DUMMYFUNCTION("""COMPUTED_VALUE"""),183469.0) -> 183469 | C18: =IFERROR(__xludf.DUMMYFUNCTION("""COMPUTED_VALUE"""),2026.0) -> 2026 | D18: =IFERROR(__xludf.DUMMYFUNCTION("""COMPUTED_VALUE"""),46386.0) -> 46386 | E18: =IFERROR(__xludf.DUMMYFUNCTION("""COMPUTED_VALUE"""),"VF") -> VF | F18: =IFERROR(__xludf.DUMMYFUNCTION("""COMPUTED_VALUE"""),1.0) -> 1 | G18: =IFERROR(__xludf.DUMMYFUNCTION("""COMPUTED_VALUE"""),"PR045") -> PR045 | H18: =IFERROR(__xludf.DUMMYFUNCTION("""COMPUTED_VALUE"""),"VD041") -> VD041 | I18: =IFERROR(__xludf.DUMMYFUNCTION("""COMPUTED_VALUE"""),14.0) -> 14 | J18: =IFERROR(__xludf.DUMMYFUNCTION("""COMPUTED_VALUE"""),1157.1) -> 1157.1 | K18: =IFERROR(__xludf.DUMMYFUNCTION("""COMPUTED_VALUE"""),1157.1) -> 1157.1
A19: =IFERROR(__xludf.DUMMYFUNCTION("""COMPUTED_VALUE"""),1000.0) -> 1000 | B19: =IFERROR(__xludf.DUMMYFUNCTION("""COMPUTED_VALUE"""),183470.0) -> 183470 | C19: =IFERROR(__xludf.DUMMYFUNCTION("""COMPUTED_VALUE"""),2026.0) -> 2026 | D19: =IFERROR(__xludf.DUMMYFUNCTION("""COMPUTED_VALUE"""),46386.0) -> 46386 | E19: =IFERROR(__xludf.DUMMYFUNCTION("""COMPUTED_VALUE"""),"VF") -> VF | F19: =IFERROR(__xludf.DUMMYFUNCTION("""COMPUTED_VALUE"""),1.0) -> 1 | G19: =IFERROR(__xludf.DUMMYFUNCTION("""COMPUTED_VALUE"""),"PR053") -> PR053 | H19: =IFERROR(__xludf.DUMMYFUNCTION("""COMPUTED_VALUE"""),"VD013") -> VD013 | I19: =IFERROR(__xludf.DUMMYFUNCTION("""COMPUTED_VALUE"""),9.0) -> 9 | J19: =IFERROR(__xludf.DUMMYFUNCTION("""COMPUTED_VALUE"""),511.97) -> 511.97 | K19: =IFERROR(__xludf.DUMMYFUNCTION("""COMPUTED_VALUE"""),511.97) -> 511.97
A20: =IFERROR(__xludf.DUMMYFUNCTION("""COMPUTED_VALUE"""),1000.0) -> 1000 | B20: =IFERROR(__xludf.DUMMYFUNCTION("""COMPUTED_VALUE"""),183471.0) -> 183471 | C20: =IFERROR(__xludf.DUMMYFUNCTION("""COMPUTED_VALUE"""),2026.0) -> 2026 | D20: =IFERROR(__xludf.DUMMYFUNCTION("""COMPUTED_VALUE"""),46386.0) -> 46386 | E20: =IFERROR(__xludf.DUMMYFUNCTION("""COMPUTED_VALUE"""),"VF") -> VF | F20: =IFERROR(__xludf.DUMMYFUNCTION("""COMPUTED_VALUE"""),1.0) -> 1 | G20: =IFERROR(__xludf.DUMMYFUNCTION("""COMPUTED_VALUE"""),"PR054") -> PR054 | H20: =IFERROR(__xludf.DUMMYFUNCTION("""COMPUTED_VALUE"""),"VD028") -> VD028 | I20: =IFERROR(__xludf.DUMMYFUNCTION("""COMPUTED_VALUE"""),9.0) -> 9 | J20: =IFERROR(__xludf.DUMMYFUNCTION("""COMPUTED_VALUE"""),538.92) -> 538.92 | K20: =IFERROR(__xludf.DUMMYFUNCTION("""COMPUTED_VALUE"""),538.92) -> 538.92
A21: =IFERROR(__xludf.DUMMYFUNCTION("""COMPUTED_VALUE"""),2000.0) -> 2000 | B21: =IFERROR(__xludf.DUMMYFUNCTION("""COMPUTED_VALUE"""),183472.0) -> 183472 | C21: =IFERROR(__xludf.DUMMYFUNCTION("""COMPUTED_VALUE"""),2026.0) -> 2026 | D21: =IFERROR(__xludf.DUMMYFUNCTION("""COMPUTED_VALUE"""),46386.0) -> 46386 | E21: =IFERROR(__xludf.DUMMYFUNCTION("""COMPUTED_VALUE"""),"VF") -> VF | F21: =IFERROR(__xludf.DUMMYFUNCTION("""COMPUTED_VALUE"""),1.0) -> 1 | G21: =IFERROR(__xludf.DUMMYFUNCTION("""COMPUTED_VALUE"""),"PR020") -> PR020 | H21: =IFERROR(__xludf.DUMMYFUNCTION("""COMPUTED_VALUE"""),"VD047") -> VD047 | I21: =IFERROR(__xludf.DUMMYFUNCTION("""COMPUTED_VALUE"""),27.0) -> 27 | J21: =IFERROR(__xludf.DUMMYFUNCTION("""COMPUTED_VALUE"""),8907.03) -> 8907.03 | K21: =IFERROR(__xludf.DUMMYFUNCTION("""COMPUTED_VALUE"""),8907.03) -> 8907.03
A22: =IFERROR(__xludf.DUMMYFUNCTION("""COMPUTED_VALUE"""),1000.0) -> 1000 | B22: =IFERROR(__xludf.DUMMYFUNCTION("""COMPUTED_VALUE"""),183472.0) -> 183472 | C22: =IFERROR(__xludf.DUMMYFUNCTION("""COMPUTED_VALUE"""),2026.0) -> 2026 | D22: =IFERROR(__xludf.DUMMYFUNCTION("""COMPUTED_VALUE"""),46386.0) -> 46386 | E22: =IFERROR(__xludf.DUMMYFUNCTION("""COMPUTED_VALUE"""),"VF") -> VF | F22: =IFERROR(__xludf.DUMMYFUNCTION("""COMPUTED_VALUE"""),2.0) -> 2 | G22: =IFERROR(__xludf.DUMMYFUNCTION("""COMPUTED_VALUE"""),"PR047") -> PR047 | H22: =IFERROR(__xludf.DUMMYFUNCTION("""COMPUTED_VALUE"""),"VD017") -> VD017 | I22: =IFERROR(__xludf.DUMMYFUNCTION("""COMPUTED_VALUE"""),12.0) -> 12 | J22: =IFERROR(__xludf.DUMMYFUNCTION("""COMPUTED_VALUE"""),4174.56) -> 4174.56 | K22: =IFERROR(__xludf.DUMMYFUNCTION("""COMPUTED_VALUE"""),4174.56) -> 4174.56
A23: =IFERROR(__xludf.DUMMYFUNCTION("""COMPUTED_VALUE"""),2000.0) -> 2000 | B23: =IFERROR(__xludf.DUMMYFUNCTION("""COMPUTED_VALUE"""),183473.0) -> 183473 | C23: =IFERROR(__xludf.DUMMYFUNCTION("""COMPUTED_VALUE"""),2026.0) -> 2026 | D23: =IFERROR(__xludf.DUMMYFUNCTION("""COMPUTED_VALUE"""),46386.0) -> 46386 | E23: =IFERROR(__xludf.DUMMYFUNCTION("""COMPUTED_VALUE"""),"VF") -> VF | F23: =IFERROR(__xludf.DUMMYFUNCTION("""COMPUTED_VALUE"""),1.0) -> 1 | G23: =IFERROR(__xludf.DUMMYFUNCTION("""COMPUTED_VALUE"""),"PR047") -> PR047 | H23: =IFERROR(__xludf.DUMMYFUNCTION("""COMPUTED_VALUE"""),"VD040") -> VD040 | I23: =IFERROR(__xludf.DUMMYFUNCTION("""COMPUTED_VALUE"""),15.0) -> 15 | J23: =IFERROR(__xludf.DUMMYFUNCTION("""COMPUTED_VALUE"""),4826.84) -> 4826.84 | K23: =IFERROR(__xludf.DUMMYFUNCTION("""COMPUTED_VALUE"""),4826.84) -> 4826.84
A24: =IFERROR(__xludf.DUMMYFUNCTION("""COMPUTED_VALUE"""),1000.0) -> 1000 | B24: =IFERROR(__xludf.DUMMYFUNCTION("""COMPUTED_VALUE"""),183474.0) -> 183474 | C24: =IFERROR(__xludf.DUMMYFUNCTION("""COMPUTED_VALUE"""),2026.0) -> 2026 | D24: =IFERROR(__xludf.DUMMYFUNCTION("""COMPUTED_VALUE"""),46386.0) -> 46386 | E24: =IFERROR(__xludf.DUMMYFUNCTION("""COMPUTED_VALUE"""),"VF") -> VF | F24: =IFERROR(__xludf.DUMMYFUNCTION("""COMPUTED_VALUE"""),1.0) -> 1 | G24: =IFERROR(__xludf.DUMMYFUNCTION("""COMPUTED_VALUE"""),"PR003") -> PR003 | H24: =IFERROR(__xludf.DUMMYFUNCTION("""COMPUTED_VALUE"""),"VD033") -> VD033 | I24: =IFERROR(__xludf.DUMMYFUNCTION("""COMPUTED_VALUE"""),8.0) -> 8 | J24: =IFERROR(__xludf.DUMMYFUNCTION("""COMPUTED_VALUE"""),629.59) -> 629.59 | K24: =IFERROR(__xludf.DUMMYFUNCTION("""COMPUTED_VALUE"""),629.59) -> 629.59
A25: =IFERROR(__xludf.DUMMYFUNCTION("""COMPUTED_VALUE"""),1000.0) -> 1000 | B25: =IFERROR(__xludf.DUMMYFUNCTION("""COMPUTED_VALUE"""),183475.0) -> 183475 | C25: =IFERROR(__xludf.DUMMYFUNCTION("""COMPUTED_VALUE"""),2026.0) -> 2026 | D25: =IFERROR(__xludf.DUMMYFUNCTION("""COMPUTED_VALUE"""),46386.0) -> 46386 | E25: =IFERROR(__xludf.DUMMYFUNCTION("""COMPUTED_VALUE"""),"VF") -> VF | F25: =IFERROR(__xludf.DUMMYFUNCTION("""COMPUTED_VALUE"""),1.0) -> 1 | G25: =IFERROR(__xludf.DUMMYFUNCTION("""COMPUTED_VALUE"""),"PR058") -> PR058 | H25: =IFERROR(__xludf.DUMMYFUNCTION("""COMPUTED_VALUE"""),"VD014") -> VD014 | I25: =IFERROR(__xludf.DUMMYFUNCTION("""COMPUTED_VALUE"""),21.0) -> 21 | J25: =IFERROR(__xludf.DUMMYFUNCTION("""COMPUTED_VALUE"""),4536.0) -> 4536 | K25: =IFERROR(__xludf.DUMMYFUNCTION("""COMPUTED_VALUE"""),4536.0) -> 4536
A26: =IFERROR(__xludf.DUMMYFUNCTION("""COMPUTED_VALUE"""),2000.0) -> 2000 | B26: =IFERROR(__xludf.DUMMYFUNCTION("""COMPUTED_VALUE"""),183476.0) -> 183476 | C26: =IFERROR(__xludf.DUMMYFUNCTION("""COMPUTED_VALUE"""),2026.0) -> 2026 | D26: =IFERROR(__xludf.DUMMYFUNCTION("""COMPUTED_VALUE"""),46386.0) -> 46386 | E26: =IFERROR(__xludf.DUMMYFUNCTION("""COMPUTED_VALUE"""),"VF") -> VF | F26: =IFERROR(__xludf.DUMMYFUNCTION("""COMPUTED_VALUE"""),1.0) -> 1 | G26: =IFERROR(__xludf.DUMMYFUNCTION("""COMPUTED_VALUE"""),"PR049") -> PR049 | H26: =IFERROR(__xludf.DUMMYFUNCTION("""COMPUTED_VALUE"""),"VD029") -> VD029 | I26: =IFERROR(__xludf.DUMMYFUNCTION("""COMPUTED_VALUE"""),12.0) -> 12 | J26: =IFERROR(__xludf.DUMMYFUNCTION("""COMPUTED_VALUE"""),473.76) -> 473.76 | K26: =IFERROR(__xludf.DUMMYFUNCTION("""COMPUTED_VALUE"""),473.76) -> 473.76
A27: =IFERROR(__xludf.DUMMYFUNCTION("""COMPUTED_VALUE"""),1000.0) -> 1000 | B27: =IFERROR(__xludf.DUMMYFUNCTION("""COMPUTED_VALUE"""),183477.0) -> 183477 | C27: =IFERROR(__xludf.DUMMYFUNCTION("""COMPUTED_VALUE"""),2026.0) -> 2026 | D27: =IFERROR(__xludf.DUMMYFUNCTION("""COMPUTED_VALUE"""),46386.0) -> 46386 | E27: =IFERROR(__xludf.DUMMYFUNCTION("""COMPUTED_VALUE"""),"VF") -> VF | F27: =IFERROR(__xludf.DUMMYFUNCTION("""COMPUTED_VALUE"""),1.0) -> 1 | G27: =IFERROR(__xludf.DUMMYFUNCTION("""COMPUTED_VALUE"""),"PR035") -> PR035 | H27: =IFERROR(__xludf.DUMMYFUNCTION("""COMPUTED_VALUE"""),"VD010") -> VD010 | I27: =IFERROR(__xludf.DUMMYFUNCTION("""COMPUTED_VALUE"""),27.0) -> 27 | J27: =IFERROR(__xludf.DUMMYFUNCTION("""COMPUTED_VALUE"""),2763.94) -> 2763.94 | K27: =IFERROR(__xludf.DUMMYFUNCTION("""COMPUTED_VALUE"""),2763.94) -> 2763.94
A28: =IFERROR(__xludf.DUMMYFUNCTION("""COMPUTED_VALUE"""),2000.0) -> 2000 | B28: =IFERROR(__xludf.DUMMYFUNCTION("""COMPUTED_VALUE"""),183478.0) -> 183478 | C28: =IFERROR(__xludf.DUMMYFUNCTION("""COMPUTED_VALUE"""),2026.0) -> 2026 | D28: =IFERROR(__xludf.DUMMYFUNCTION("""COMPUTED_VALUE"""),46386.0) -> 46386 | E28: =IFERROR(__xludf.DUMMYFUNCTION("""COMPUTED_VALUE"""),"VF") -> VF | F28: =IFERROR(__xludf.DUMMYFUNCTION("""COMPUTED_VALUE"""),1.0) -> 1 | G28: =IFERROR(__xludf.DUMMYFUNCTION("""COMPUTED_VALUE"""),"PR003") -> PR003 | H28: =IFERROR(__xludf.DUMMYFUNCTION("""COMPUTED_VALUE"""),"VD024") -> VD024 | I28: =IFERROR(__xludf.DUMMYFUNCTION("""COMPUTED_VALUE"""),18.0) -> 18 | J28: =IFERROR(__xludf.DUMMYFUNCTION("""COMPUTED_VALUE"""),1480.39) -> 1480.39 | K28: =IFERROR(__xludf.DUMMYFUNCTION("""COMPUTED_VALUE"""),1480.39) -> 1480.39
A29: =IFERROR(__xludf.DUMMYFUNCTION("""COMPUTED_VALUE"""),2000.0) -> 2000 | B29: =IFERROR(__xludf.DUMMYFUNCTION("""COMPUTED_VALUE"""),183479.0) -> 183479 | C29: =IFERROR(__xludf.DUMMYFUNCTION("""COMPUTED_VALUE"""),2026.0) -> 2026 | D29: =IFERROR(__xludf.DUMMYFUNCTION("""COMPUTED_VALUE"""),46385.0) -> 46385 | E29: =IFERROR(__xludf.DUMMYFUNCTION("""COMPUTED_VALUE"""),"VF") -> VF | F29: =IFERROR(__xludf.DUMMYFUNCTION("""COMPUTED_VALUE"""),1.0) -> 1 | G29: =IFERROR(__xludf.DUMMYFUNCTION("""COMPUTED_VALUE"""),"PR006") -> PR006 | H29: =IFERROR(__xludf.DUMMYFUNCTION("""COMPUTED_VALUE"""),"VD021") -> VD021 | I29: =IFERROR(__xludf.DUMMYFUNCTION("""COMPUTED_VALUE"""),27.0) -> 27 | J29: =IFERROR(__xludf.DUMMYFUNCTION("""COMPUTED_VALUE"""),1249.67) -> 1249.67 | K29: =IFERROR(__xludf.DUMMYFUNCTION("""COMPUTED_VALUE"""),1249.67) -> 1249.67
A30: =IFERROR(__xludf.DUMMYFUNCTION("""COMPUTED_VALUE"""),1000.0) -> 1000 | B30: =IFERROR(__xludf.DUMMYFUNCTION("""COMPUTED_VALUE"""),183479.0) -> 183479 | C30: =IFERROR(__xludf.DUMMYFUNCTION("""COMPUTED_VALUE"""),2026.0) -> 2026 | D30: =IFERROR(__xludf.DUMMYFUNCTION("""COMPUTED_VALUE"""),46385.0) -> 46385 | E30: =IFERROR(__xludf.DUMMYFUNCTION("""COMPUTED_VALUE"""),"VF") -> VF | F30: =IFERROR(__xludf.DUMMYFUNCTION("""COMPUTED_VALUE"""),2.0) -> 2 | G30: =IFERROR(__xludf.DUMMYFUNCTION("""COMPUTED_VALUE"""),"PR002") -> PR002 | H30: =IFERROR(__xludf.DUMMYFUNCTION("""COMPUTED_VALUE"""),"VD040") -> VD040 | I30: =IFERROR(__xludf.DUMMYFUNCTION("""COMPUTED_VALUE"""),24.0) -> 24 | J30: =IFERROR(__xludf.DUMMYFUNCTION("""COMPUTED_VALUE"""),1996.34) -> 1996.34 | K30: =IFERROR(__xludf.DUMMYFUNCTION("""COMPUTED_VALUE"""),1996.34) -> 1996.34
A31: =IFERROR(__xludf.DUMMYFUNCTION("""COMPUTED_VALUE"""),1000.0) -> 1000 | B31: =IFERROR(__xludf.DUMMYFUNCTION("""COMPUTED_VALUE"""),183479.0) -> 183479 | C31: =IFERROR(__xludf.DUMMYFUNCTION("""COMPUTED_VALUE"""),2026.0) -> 2026 | D31: =IFERROR(__xludf.DUMMYFUNCTION("""COMPUTED_VALUE"""),46384.0) -> 46384 | E31: =IFERROR(__xludf.DUMMYFUNCTION("""COMPUTED_VALUE"""),"VF") -> VF | F31: =IFERROR(__xludf.DUMMYFUNCTION("""COMPUTED_VALUE"""),3.0) -> 3 | G31: =IFERROR(__xludf.DUMMYFUNCTION("""COMPUTED_VALUE"""),"PR038") -> PR038 | H31: =IFERROR(__xludf.DUMMYFUNCTION("""COMPUTED_VALUE"""),"VD016") -> VD016 | I31: =IFERROR(__xludf.DUMMYFUNCTION("""COMPUTED_VALUE"""),12.0) -> 12 | J31: =IFERROR(__xludf.DUMMYFUNCTION("""COMPUTED_VALUE"""),1972.02) -> 1972.02 | K31: =IFERROR(__xludf.DUMMYFUNCTION("""COMPUTED_VALUE"""),1972.02) -> 1972.02
A32: =IFERROR(__xludf.DUMMYFUNCTION("""COMPUTED_VALUE"""),1000.0) -> 1000 | B32: =IFERROR(__xludf.DUMMYFUNCTION("""COMPUTED_VALUE"""),183480.0) -> 183480 | C32: =IFERROR(__xludf.DUMMYFUNCTION("""COMPUTED_VALUE"""),2026.0) -> 2026 | D32: =IFERROR(__xludf.DUMMYFUNCTION("""COMPUTED_VALUE"""),46384.0) -> 46384 | E32: =IFERROR(__xludf.DUMMYFUNCTION("""COMPUTED_VALUE"""),"VF") -> VF | F32: =IFERROR(__xludf.DUMMYFUNCTION("""COMPUTED_VALUE"""),1.0) -> 1 | G32: =IFERROR(__xludf.DUMMYFUNCTION("""COMPUTED_VALUE"""),"PR027") -> PR027 | H32: =IFERROR(__xludf.DUMMYFUNCTION("""COMPUTED_VALUE"""),"VD035") -> VD035 | I32: =IFERROR(__xludf.DUMMYFUNCTION("""COMPUTED_VALUE"""),30.0) -> 30 | J32: =IFERROR(__xludf.DUMMYFUNCTION("""COMPUTED_VALUE"""),3996.0) -> 3996 | K32: =IFERROR(__xludf.DUMMYFUNCTION("""COMPUTED_VALUE"""),3996.0) -> 3996
A33: =IFERROR(__xludf.DUMMYFUNCTION("""COMPUTED_VALUE"""),1000.0) -> 1000 | B33: =IFERROR(__xludf.DUMMYFUNCTION("""COMPUTED_VALUE"""),183480.0) -> 183480 | C33: =IFERROR(__xludf.DUMMYFUNCTION("""COMPUTED_VALUE"""),2026.0) -> 2026 | D33: =IFERROR(__xludf.DUMMYFUNCTION("""COMPUTED_VALUE"""),46384.0) -> 46384 | E33: =IFERROR(__xludf.DUMMYFUNCTION("""COMPUTED_VALUE"""),"VF") -> VF | F33: =IFERROR(__xludf.DUMMYFUNCTION("""COMPUTED_VALUE"""),2.0) -> 2 | G33: =IFERROR(__xludf.DUMMYFUNCTION("""COMPUTED_VALUE"""),"PR059") -> PR059 | H33: =IFERROR(__xludf.DUMMYFUNCTION("""COMPUTED_VALUE"""),"VD049") -> VD049 | I33: =IFERROR(__xludf.DUMMYFUNCTION("""COMPUTED_VALUE"""),12.0) -> 12 | J33: =IFERROR(__xludf.DUMMYFUNCTION("""COMPUTED_VALUE"""),2419.2) -> 2419.2 | K33: =IFERROR(__xludf.DUMMYFUNCTION("""COMPUTED_VALUE"""),2419.2) -> 2419.2
A34: =IFERROR(__xludf.DUMMYFUNCTION("""COMPUTED_VALUE"""),1000.0) -> 1000 | B34: =IFERROR(__xludf.DUMMYFUNCTION("""COMPUTED_VALUE"""),183480.0) -> 183480 | C34: =IFERROR(__xludf.DUMMYFUNCTION("""COMPUTED_VALUE"""),2026.0) -> 2026 | D34: =IFERROR(__xludf.DUMMYFUNCTION("""COMPUTED_VALUE"""),46383.0) -> 46383 | E34: =IFERROR(__xludf.DUMMYFUNCTION("""COMPUTED_VALUE"""),"VF") -> VF | F34: =IFERROR(__xludf.DUMMYFUNCTION("""COMPUTED_VALUE"""),3.0) -> 3 | G34: =IFERROR(__xludf.DUMMYFUNCTION("""COMPUTED_VALUE"""),"PR035") -> PR035 | H34: =IFERROR(__xludf.DUMMYFUNCTION("""COMPUTED_VALUE"""),"VD019") -> VD019 | I34: =IFERROR(__xludf.DUMMYFUNCTION("""COMPUTED_VALUE"""),21.0) -> 21 | J34: =IFERROR(__xludf.DUMMYFUNCTION("""COMPUTED_VALUE"""),2207.31) -> 2207.31 | K34: =IFERROR(__xludf.DUMMYFUNCTION("""COMPUTED_VALUE"""),2207.31) -> 2207.31
A35: =IFERROR(__xludf.DUMMYFUNCTION("""COMPUTED_VALUE"""),1000.0) -> 1000 | B35: =IFERROR(__xludf.DUMMYFUNCTION("""COMPUTED_VALUE"""),183481.0) -> 183481 | C35: =IFERROR(__xludf.DUMMYFUNCTION("""COMPUTED_VALUE"""),2026.0) -> 2026 | D35: =IFERROR(__xludf.DUMMYFUNCTION("""COMPUTED_VALUE"""),46383.0) -> 46383 | E35: =IFERROR(__xludf.DUMMYFUNCTION("""COMPUTED_VALUE"""),"VF") -> VF | F35: =IFERROR(__xludf.DUMMYFUNCTION("""COMPUTED_VALUE"""),1.0) -> 1 | G35: =IFERROR(__xludf.DUMMYFUNCTION("""COMPUTED_VALUE"""),"PR028") -> PR028 | H35: =IFERROR(__xludf.DUMMYFUNCTION("""COMPUTED_VALUE"""),"VD011") -> VD011 | I35: =IFERROR(__xludf.DUMMYFUNCTION("""COMPUTED_VALUE"""),16.0) -> 16 | J35: =IFERROR(__xludf.DUMMYFUNCTION("""COMPUTED_VALUE"""),4718.11) -> 4718.11 | K35: =IFERROR(__xludf.DUMMYFUNCTION("""COMPUTED_VALUE"""),4718.11) -> 4718.11
A36: =IFERROR(__xludf.DUMMYFUNCTION("""COMPUTED_VALUE"""),1000.0) -> 1000 | B36: =IFERROR(__xludf.DUMMYFUNCTION("""COMPUTED_VALUE"""),183482.0) -> 183482 | C36: =IFERROR(__xludf.DUMMYFUNCTION("""COMPUTED_VALUE"""),2026.0) -> 2026 | D36: =IFERROR(__xludf.DUMMYFUNCTION("""COMPUTED_VALUE"""),46382.0) -> 46382 | E36: =IFERROR(__xludf.DUMMYFUNCTION("""COMPUTED_VALUE"""),"VF") -> VF | F36: =IFERROR(__xludf.DUMMYFUNCTION("""COMPUTED_VALUE"""),1.0) -> 1 | G36: =IFERROR(__xludf.DUMMYFUNCTION("""COMPUTED_VALUE"""),"PR018") -> PR018 | H36: =IFERROR(__xludf.DUMMYFUNCTION("""COMPUTED_VALUE"""),"VD016") -> VD016 | I36: =IFERROR(__xludf.DUMMYFUNCTION("""COMPUTED_VALUE"""),10.0) -> 10 | J36: =IFERROR(__xludf.DUMMYFUNCTION("""COMPUTED_VALUE"""),378.35) -> 378.35 | K36: =IFERROR(__xludf.DUMMYFUNCTION("""COMPUTED_VALUE"""),378.35) -> 378.35
A37: =IFERROR(__xludf.DUMMYFUNCTION("""COMPUTED_VALUE"""),2000.0) -> 2000 | B37: =IFERROR(__xludf.DUMMYFUNCTION("""COMPUTED_VALUE"""),183483.0) -> 183483 | C37: =IFERROR(__xludf.DUMMYFUNCTION("""COMPUTED_VALUE"""),2026.0) -> 2026 | D37: =IFERROR(__xludf.DUMMYFUNCTION("""COMPUTED_VALUE"""),46382.0) -> 46382 | E37: =IFERROR(__xludf.DUMMYFUNCTION("""COMPUTED_VALUE"""),"VF") -> VF | F37: =IFERROR(__xludf.DUMMYFUNCTION("""COMPUTED_VALUE"""),1.0) -> 1 | G37: =IFERROR(__xludf.DUMMYFUNCTION("""COMPUTED_VALUE"""),"PR035") -> PR035 | H37: =IFERROR(__xludf.DUMMYFUNCTION("""COMPUTED_VALUE"""),"VD018") -> VD018 | I37: =IFERROR(__xludf.DUMMYFUNCTION("""COMPUTED_VALUE"""),28.0) -> 28 | J37: =IFERROR(__xludf.DUMMYFUNCTION("""COMPUTED_VALUE"""),2149.73) -> 2149.73 | K37: =IFERROR(__xludf.DUMMYFUNCTION("""COMPUTED_VALUE"""),2149.73) -> 2149.73
A38: =IFERROR(__xludf.DUMMYFUNCTION("""COMPUTED_VALUE"""),1000.0) -> 1000 | B38: =IFERROR(__xludf.DUMMYFUNCTION("""COMPUTED_VALUE"""),183483.0) -> 183483 | C38: =IFERROR(__xludf.DUMMYFUNCTION("""COMPUTED_VALUE"""),2026.0) -> 2026 | D38: =IFERROR(__xludf.DUMMYFUNCTION("""COMPUTED_VALUE"""),46381.0) -> 46381 | E38: =IFERROR(__xludf.DUMMYFUNCTION("""COMPUTED_VALUE"""),"VF") -> VF | F38: =IFERROR(__xludf.DUMMYFUNCTION("""COMPUTED_VALUE"""),2.0) -> 2 | G38: =IFERROR(__xludf.DUMMYFUNCTION("""COMPUTED_VALUE"""),"PR057") -> PR057 | H38: =IFERROR(__xludf.DUMMYFUNCTION("""COMPUTED_VALUE"""),"VD034") -> VD034 | I38: =IFERROR(__xludf.DUMMYFUNCTION("""COMPUTED_VALUE"""),9.0) -> 9 | J38: =IFERROR(__xludf.DUMMYFUNCTION("""COMPUTED_VALUE"""),906.19) -> 906.19 | K38: =IFERROR(__xludf.DUMMYFUNCTION("""COMPUTED_VALUE"""),906.19) -> 906.19
A39: =IFERROR(__xludf.DUMMYFUNCTION("""COMPUTED_VALUE"""),1000.0) -> 1000 | B39: =IFERROR(__xludf.DUMMYFUNCTION("""COMPUTED_VALUE"""),183484.0) -> 183484 | C39: =IFERROR(__xludf.DUMMYFUNCTION("""COMPUTED_VALUE"""),2026.0) -> 2026 | D39: =IFERROR(__xludf.DUMMYFUNCTION("""COMPUTED_VALUE"""),46381.0) -> 46381 | E39: =IFERROR(__xludf.DUMMYFUNCTION("""COMPUTED_VALUE"""),"VF") -> VF | F39: =IFERROR(__xludf.DUMMYFUNCTION("""COMPUTED_VALUE"""),1.0) -> 1 | G39: =IFERROR(__xludf.DUMMYFUNCTION("""COMPUTED_VALUE"""),"PR004") -> PR004 | H39: =IFERROR(__xludf.DUMMYFUNCTION("""COMPUTED_VALUE"""),"VD024") -> VD024 | I39: =IFERROR(__xludf.DUMMYFUNCTION("""COMPUTED_VALUE"""),15.0) -> 15 | J39: =IFERROR(__xludf.DUMMYFUNCTION("""COMPUTED_VALUE"""),2610.0) -> 2610 | K39: =IFERROR(__xludf.DUMMYFUNCTION("""COMPUTED_VALUE"""),2610.0) -> 2610
A40: =IFERROR(__xludf.DUMMYFUNCTION("""COMPUTED_VALUE"""),1000.0) -> 1000 | B40: =IFERROR(__xludf.DUMMYFUNCTION("""COMPUTED_VALUE"""),183485.0) -> 183485 | C40: =IFERROR(__xludf.DUMMYFUNCTION("""COMPUTED_VALUE"""),2026.0) -> 2026 | D40: =IFERROR(__xludf.DUMMYFUNCTION("""COMPUTED_VALUE"""),46381.0) -> 46381 | E40: =IFERROR(__xludf.DUMMYFUNCTION("""COMPUTED_VALUE"""),"VF") -> VF | F40: =IFERROR(__xludf.DUMMYFUNCTION("""COMPUTED_VALUE"""),1.0) -> 1 | G40: =IFERROR(__xludf.DUMMYFUNCTION("""COMPUTED_VALUE"""),"PR014") -> PR014 | H40: =IFERROR(__xludf.DUMMYFUNCTION("""COMPUTED_VALUE"""),"VD011") -> VD011 | I40: =IFERROR(__xludf.DUMMYFUNCTION("""COMPUTED_VALUE"""),12.0) -> 12 | J40: =IFERROR(__xludf.DUMMYFUNCTION("""COMPUTED_VALUE"""),560.2) -> 560.2 | K40: =IFERROR(__xludf.DUMMYFUNCTION("""COMPUTED_VALUE"""),560.2) -> 560.2
...

Sheet Productos
A1: =IFERROR(__xludf.DUMMYFUNCTION("IMPORTRANGE(""https://docs.google.com/spreadsheets/d/1wDatiNabBWFvhbng0IgSrI0LbZ9kw3ciTUIdsOHVncU"",""A1:F100"")"),"#REF!") -> #REF!

Sheet Vendedores
A1: =IFERROR(__xludf.DUMMYFUNCTION("IMPORTRANGE(""https://docs.google.com/spreadsheets/d/1vaJzUnOrtKtLng2PhfFKCWSC4LAsqa8tmcEg1rv0FIM/"",""A1:D50"")"),"#REF!") -> #REF!

Sheet Datos Ventas CSV
A1: =IFERROR(__xludf.DUMMYFUNCTION("query(importdata(""https://drive.google.com/uc?export=download&id=1U1AR8u12BH41vb1Uvb31WaPc4KTs4qQo&v=2"","";""),""SELECT Col7, Col8, Col9, Col10"")"),"Material") -> Material | B1: =IFERROR(__xludf.DUMMYFUNCTION("""COMPUTED_VALUE"""),"Vendedor") -> Vendedor | C1: =IFERROR(__xludf.DUMMYFUNCTION("""COMPUTED_VALUE"""),"Cantidad") -> Cantidad | D1: =IFERROR(__xludf.DUMMYFUNCTION("""COMPUTED_VALUE"""),"Valor en Moneda Local") -> Valor en Moneda Local
A2: =IFERROR(__xludf.DUMMYFUNCTION("""COMPUTED_VALUE"""),"PR001") -> PR001 | B2: =IFERROR(__xludf.DUMMYFUNCTION("""COMPUTED_VALUE"""),"VD026") -> VD026 | C2: =IFERROR(__xludf.DUMMYFUNCTION("""COMPUTED_VALUE"""),27.0) -> 27 | D2: =IFERROR(__xludf.DUMMYFUNCTION("""COMPUTED_VALUE"""),1957.23) -> 1957.23
A3: =IFERROR(__xludf.DUMMYFUNCTION("""COMPUTED_VALUE"""),"PR058") -> PR058 | B3: =IFERROR(__xludf.DUMMYFUNCTION("""COMPUTED_VALUE"""),"VD037") -> VD037 | C3: =IFERROR(__xludf.DUMMYFUNCTION("""COMPUTED_VALUE"""),14.0) -> 14 | D3: =IFERROR(__xludf.DUMMYFUNCTION("""COMPUTED_VALUE"""),2872.8) -> 2872.8
A4: =IFERROR(__xludf.DUMMYFUNCTION("""COMPUTED_VALUE"""),"PR020") -> PR020 | B4: =IFERROR(__xludf.DUMMYFUNCTION("""COMPUTED_VALUE"""),"VD034") -> VD034 | C4: =IFERROR(__xludf.DUMMYFUNCTION("""COMPUTED_VALUE"""),20.0) -> 20 | D4: =IFERROR(__xludf.DUMMYFUNCTION("""COMPUTED_VALUE"""),7137.62) -> 7137.62
A5: =IFERROR(__xludf.DUMMYFUNCTION("""COMPUTED_VALUE"""),"PR035") -> PR035 | B5: =IFERROR(__xludf.DUMMYFUNCTION("""COMPUTED_VALUE"""),"VD021") -> VD021 | C5: =IFERROR(__xludf.DUMMYFUNCTION("""COMPUTED_VALUE"""),24.0) -> 24 | D5: =IFERROR(__xludf.DUMMYFUNCTION("""COMPUTED_VALUE"""),2478.77) -> 2478.77
A6: =IFERROR(__xludf.DUMMYFUNCTION("""COMPUTED_VALUE"""),"PR016") -> PR016 | B6: =IFERROR(__xludf.DUMMYFUNCTION("""COMPUTED_VALUE"""),"VD027") -> VD027 | C6: =IFERROR(__xludf.DUMMYFUNCTION("""COMPUTED_VALUE"""),10.0) -> 10 | D6: =IFERROR(__xludf.DUMMYFUNCTION("""COMPUTED_VALUE"""),303.03) -> 303.03
A7: =IFERROR(__xludf.DUMMYFUNCTION("""COMPUTED_VALUE"""),"PR051") -> PR051 | B7: =IFERROR(__xludf.DUMMYFUNCTION("""COMPUTED_VALUE"""),"VD048") -> VD048 | C7: =IFERROR(__xludf.DUMMYFUNCTION("""COMPUTED_VALUE"""),18.0) -> 18 | D7: =IFERROR(__xludf.DUMMYFUNCTION("""COMPUTED_VALUE"""),704.72) -> 704.72
A8: =IFERROR(__xludf.DUMMYFUNCTION("""COMPUTED_VALUE"""),"PR042") -> PR042 | B8: =IFERROR(__xludf.DUMMYFUNCTION("""COMPUTED_VALUE"""),"VD025") -> VD025 | C8: =IFERROR(__xludf.DUMMYFUNCTION("""COMPUTED_VALUE"""),27.0) -> 27 | D8: =IFERROR(__xludf.DUMMYFUNCTION("""COMPUTED_VALUE"""),1778.76) -> 1778.76
A9: =IFERROR(__xludf.DUMMYFUNCTION("""COMPUTED_VALUE"""),"PR050") -> PR050 | B9: =IFERROR(__xludf.DUMMYFUNCTION("""COMPUTED_VALUE"""),"VD037") -> VD037 | C9: =IFERROR(__xludf.DUMMYFUNCTION("""COMPUTED_VALUE"""),14.0) -> 14 | D9: =IFERROR(__xludf.DUMMYFUNCTION("""COMPUTED_VALUE"""),511.27) -> 511.27
A10: =IFERROR(__xludf.DUMMYFUNCTION("""COMPUTED_VALUE"""),"PR001") -> PR001 | B10: =IFERROR(__xludf.DUMMYFUNCTION("""COMPUTED_VALUE"""),"VD036") -> VD036 | C10: =IFERROR(__xludf.DUMMYFUNCTION("""COMPUTED_VALUE"""),12.0) -> 12 | D10: =IFERROR(__xludf.DUMMYFUNCTION("""COMPUTED_VALUE"""),901.51) -> 901.51
A11: =IFERROR(__xludf.DUMMYFUNCTION("""COMPUTED_VALUE"""),"PR059") -> PR059 | B11: =IFERROR(__xludf.DUMMYFUNCTION("""COMPUTED_VALUE"""),"VD049") -> VD049 | C11: =IFERROR(__xludf.DUMMYFUNCTION("""COMPUTED_VALUE"""),27.0) -> 27 | D11: =IFERROR(__xludf.DUMMYFUNCTION("""COMPUTED_VALUE"""),5783.4) -> 5783.4
A12: =IFERROR(__xludf.DUMMYFUNCTION("""COMPUTED_VALUE"""),"PR019") -> PR019 | B12: =IFERROR(__xludf.DUMMYFUNCTION("""COMPUTED_VALUE"""),"VD021") -> VD021 | C12: =IFERROR(__xludf.DUMMYFUNCTION("""COMPUTED_VALUE"""),15.0) -> 15 | D12: =IFERROR(__xludf.DUMMYFUNCTION("""COMPUTED_VALUE"""),845.81) -> 845.81
A13: =IFERROR(__xludf.DUMMYFUNCTION("""COMPUTED_VALUE"""),"PR055") -> PR055 | B13: =IFERROR(__xludf.DUMMYFUNCTION("""COMPUTED_VALUE"""),"VD015") -> VD015 | C13: =IFERROR(__xludf.DUMMYFUNCTION("""COMPUTED_VALUE"""),18.0) -> 18 | D13: =IFERROR(__xludf.DUMMYFUNCTION("""COMPUTED_VALUE"""),1844.75) -> 1844.75
A14: =IFERROR(__xludf.DUMMYFUNCTION("""COMPUTED_VALUE"""),"PR052") -> PR052 | B14: =IFERROR(__xludf.DUMMYFUNCTION("""COMPUTED_VALUE"""),"VD012") -> VD012 | C14: =IFERROR(__xludf.DUMMYFUNCTION("""COMPUTED_VALUE"""),16.0) -> 16 | D14: =IFERROR(__xludf.DUMMYFUNCTION("""COMPUTED_VALUE"""),950.1) -> 950.1
A15: =IFERROR(__xludf.DUMMYFUNCTION("""COMPUTED_VALUE"""),"PR052") -> PR052 | B15: =IFERROR(__xludf.DUMMYFUNCTION("""COMPUTED_VALUE"""),"VD043") -> VD043 | C15: =IFERROR(__xludf.DUMMYFUNCTION("""COMPUTED_VALUE"""),9.0) -> 9 | D15: =IFERROR(__xludf.DUMMYFUNCTION("""COMPUTED_VALUE"""),511.97) -> 511.97
A16: =IFERROR(__xludf.DUMMYFUNCTION("""COMPUTED_VALUE"""),"PR014") -> PR014 | B16: =IFERROR(__xludf.DUMMYFUNCTION("""COMPUTED_VALUE"""),"VD020") -> VD020 | C16: =IFERROR(__xludf.DUMMYFUNCTION("""COMPUTED_VALUE"""),9.0) -> 9 | D16: =IFERROR(__xludf.DUMMYFUNCTION("""COMPUTED_VALUE"""),420.15) -> 420.15
A17: =IFERROR(__xludf.DUMMYFUNCTION("""COMPUTED_VALUE"""),"PR055") -> PR055 | B17: =IFERROR(__xludf.DUMMYFUNCTION("""COMPUTED_VALUE"""),"VD019") -> VD019 | C17: =IFERROR(__xludf.DUMMYFUNCTION("""COMPUTED_VALUE"""),9.0) -> 9 | D17: =IFERROR(__xludf.DUMMYFUNCTION("""COMPUTED_VALUE"""),890.01) -> 890.01
A18: =IFERROR(__xludf.DUMMYFUNCTION("""COMPUTED_VALUE"""),"PR045") -> PR045 | B18: =IFERROR(__xludf.DUMMYFUNCTION("""COMPUTED_VALUE"""),"VD041") -> VD041 | C18: =IFERROR(__xludf.DUMMYFUNCTION("""COMPUTED_VALUE"""),14.0) -> 14 | D18: =IFERROR(__xludf.DUMMYFUNCTION("""COMPUTED_VALUE"""),1157.1) -> 1157.1
A19: =IFERROR(__xludf.DUMMYFUNCTION("""COMPUTED_VALUE"""),"PR053") -> PR053 | B19: =IFERROR(__xludf.DUMMYFUNCTION("""COMPUTED_VALUE"""),"VD013") -> VD013 | C19: =IFERROR(__xludf.DUMMYFUNCTION("""COMPUTED_VALUE"""),9.0) -> 9 | D19: =IFERROR(__xludf.DUMMYFUNCTION("""COMPUTED_VALUE"""),511.97) -> 511.97
A20: =IFERROR(__xludf.DUMMYFUNCTION("""COMPUTED_VALUE"""),"PR054") -> PR054 | B20: =IFERROR(__xludf.DUMMYFUNCTION("""COMPUTED_VALUE"""),"VD028") -> VD028 | C20: =IFERROR(__xludf.DUMMYFUNCTION("""COMPUTED_VALUE"""),9.0) -> 9 | D20: =IFERROR(__xludf.DUMMYFUNCTION("""COMPUTED_VALUE"""),538.92) -> 538.92
A21: =IFERROR(__xludf.DUMMYFUNCTION("""COMPUTED_VALUE"""),"PR020") -> PR020 | B21: =IFERROR(__xludf.DUMMYFUNCTION("""COMPUTED_VALUE"""),"VD047") -> VD047 | C21: =IFERROR(__xludf.DUMMYFUNCTION("""COMPUTED_VALUE"""),27.0) -> 27 | D21: =IFERROR(__xludf.DUMMYFUNCTION("""COMPUTED_VALUE"""),8907.03) -> 8907.03
A22: =IFERROR(__xludf.DUMMYFUNCTION("""COMPUTED_VALUE"""),"PR047") -> PR047 | B22: =IFERROR(__xludf.DUMMYFUNCTION("""COMPUTED_VALUE"""),"VD017") -> VD017 | C22: =IFERROR(__xludf.DUMMYFUNCTION("""COMPUTED_VALUE"""),12.0) -> 12 | D22: =IFERROR(__xludf.DUMMYFUNCTION("""COMPUTED_VALUE"""),4174.56) -> 4174.56
A23: =IFERROR(__xludf.DUMMYFUNCTION("""COMPUTED_VALUE"""),"PR047") -> PR047 | B23: =IFERROR(__xludf.DUMMYFUNCTION("""COMPUTED_VALUE"""),"VD040") -> VD040 | C23: =IFERROR(__xludf.DUMMYFUNCTION("""COMPUTED_VALUE"""),15.0) -> 15 | D23: =IFERROR(__xludf.DUMMYFUNCTION("""COMPUTED_VALUE"""),4826.84) -> 4826.84
A24: =IFERROR(__xludf.DUMMYFUNCTION("""COMPUTED_VALUE"""),"PR003") -> PR003 | B24: =IFERROR(__xludf.DUMMYFUNCTION("""COMPUTED_VALUE"""),"VD033") -> VD033 | C24: =IFERROR(__xludf.DUMMYFUNCTION("""COMPUTED_VALUE"""),8.0) -> 8 | D24: =IFERROR(__xludf.DUMMYFUNCTION("""COMPUTED_VALUE"""),629.59) -> 629.59
A25: =IFERROR(__xludf.DUMMYFUNCTION("""COMPUTED_VALUE"""),"PR058") -> PR058 | B25: =IFERROR(__xludf.DUMMYFUNCTION("""COMPUTED_VALUE"""),"VD014") -> VD014 | C25: =IFERROR(__xludf.DUMMYFUNCTION("""COMPUTED_VALUE"""),21.0) -> 21 | D25: =IFERROR(__xludf.DUMMYFUNCTION("""COMPUTED_VALUE"""),4536.0) -> 4536
A26: =IFERROR(__xludf.DUMMYFUNCTION("""COMPUTED_VALUE"""),"PR049") -> PR049 | B26: =IFERROR(__xludf.DUMMYFUNCTION("""COMPUTED_VALUE"""),"VD029") -> VD029 | C26: =IFERROR(__xludf.DUMMYFUNCTION("""COMPUTED_VALUE"""),12.0) -> 12 | D26: =IFERROR(__xludf.DUMMYFUNCTION("""COMPUTED_VALUE"""),473.76) -> 473.76
A27: =IFERROR(__xludf.DUMMYFUNCTION("""COMPUTED_VALUE"""),"PR035") -> PR035 | B27: =IFERROR(__xludf.DUMMYFUNCTION("""COMPUTED_VALUE"""),"VD010") -> VD010 | C27: =IFERROR(__xludf.DUMMYFUNCTION("""COMPUTED_VALUE"""),27.0) -> 27 | D27: =IFERROR(__xludf.DUMMYFUNCTION("""COMPUTED_VALUE"""),2763.94) -> 2763.94
A28: =IFERROR(__xludf.DUMMYFUNCTION("""COMPUTED_VALUE"""),"PR003") -> PR003 | B28: =IFERROR(__xludf.DUMMYFUNCTION("""COMPUTED_VALUE"""),"VD024") -> VD024 | C28: =IFERROR(__xludf.DUMMYFUNCTION("""COMPUTED_VALUE"""),18.0) -> 18 | D28: =IFERROR(__xludf.DUMMYFUNCTION("""COMPUTED_VALUE"""),1480.39) -> 1480.39
A29: =IFERROR(__xludf.DUMMYFUNCTION("""COMPUTED_VALUE"""),"PR006") -> PR006 | B29: =IFERROR(__xludf.DUMMYFUNCTION("""COMPUTED_VALUE"""),"VD021") -> VD021 | C29: =IFERROR(__xludf.DUMMYFUNCTION("""COMPUTED_VALUE"""),27.0) -> 27 | D29: =IFERROR(__xludf.DUMMYFUNCTION("""COMPUTED_VALUE"""),1249.67) -> 1249.67
A30: =IFERROR(__xludf.DUMMYFUNCTION("""COMPUTED_VALUE"""),"PR002") -> PR002 | B30: =IFERROR(__xludf.DUMMYFUNCTION("""COMPUTED_VALUE"""),"VD040") -> VD040 | C30: =IFERROR(__xludf.DUMMYFUNCTION("""COMPUTED_VALUE"""),24.0) -> 24 | D30: =IFERROR(__xludf.DUMMYFUNCTION("""COMPUTED_VALUE"""),1996.34) -> 1996.34
A31: =IFERROR(__xludf.DUMMYFUNCTION("""COMPUTED_VALUE"""),"PR038") -> PR038 | B31: =IFERROR(__xludf.DUMMYFUNCTION("""COMPUTED_VALUE"""),"VD016") -> VD016 | C31: =IFERROR(__xludf.DUMMYFUNCTION("""COMPUTED_VALUE"""),12.0) -> 12 | D31: =IFERROR(__xludf.DUMMYFUNCTION("""COMPUTED_VALUE"""),1972.02) -> 1972.02
A32: =IFERROR(__xludf.DUMMYFUNCTION("""COMPUTED_VALUE"""),"PR027") -> PR027 | B32: =IFERROR(__xludf.DUMMYFUNCTION("""COMPUTED_VALUE"""),"VD035") -> VD035 | C32: =IFERROR(__xludf.DUMMYFUNCTION("""COMPUTED_VALUE"""),30.0) -> 30 | D32: =IFERROR(__xludf.DUMMYFUNCTION("""COMPUTED_VALUE"""),3996.0) -> 3996
A33: =IFERROR(__xludf.DUMMYFUNCTION("""COMPUTED_VALUE"""),"PR059") -> PR059 | B33: =IFERROR(__xludf.DUMMYFUNCTION("""COMPUTED_VALUE"""),"VD049") -> VD049 | C33: =IFERROR(__xludf.DUMMYFUNCTION("""COMPUTED_VALUE"""),12.0) -> 12 | D33: =IFERROR(__xludf.DUMMYFUNCTION("""COMPUTED_VALUE"""),2419.2) -> 2419.2
A34: =IFERROR(__xludf.DUMMYFUNCTION("""COMPUTED_VALUE"""),"PR035") -> PR035 | B34: =IFERROR(__xludf.DUMMYFUNCTION("""COMPUTED_VALUE"""),"VD019") -> VD019 | C34: =IFERROR(__xludf.DUMMYFUNCTION("""COMPUTED_VALUE"""),21.0) -> 21 | D34: =IFERROR(__xludf.DUMMYFUNCTION("""COMPUTED_VALUE"""),2207.31) -> 2207.31
A35: =IFERROR(__xludf.DUMMYFUNCTION("""COMPUTED_VALUE"""),"PR028") -> PR028 | B35: =IFERROR(__xludf.DUMMYFUNCTION("""COMPUTED_VALUE"""),"VD011") -> VD011 | C35: =IFERROR(__xludf.DUMMYFUNCTION("""COMPUTED_VALUE"""),16.0) -> 16 | D35: =IFERROR(__xludf.DUMMYFUNCTION("""COMPUTED_VALUE"""),4718.11) -> 4718.11
A36: =IFERROR(__xludf.DUMMYFUNCTION("""COMPUTED_VALUE"""),"PR018") -> PR018 | B36: =IFERROR(__xludf.DUMMYFUNCTION("""COMPUTED_VALUE"""),"VD016") -> VD016 | C36: =IFERROR(__xludf.DUMMYFUNCTION("""COMPUTED_VALUE"""),10.0) -> 10 | D36: =IFERROR(__xludf.DUMMYFUNCTION("""COMPUTED_VALUE"""),378.35) -> 378.35
A37: =IFERROR(__xludf.DUMMYFUNCTION("""COMPUTED_VALUE"""),"PR035") -> PR035 | B37: =IFERROR(__xludf.DUMMYFUNCTION("""COMPUTED_VALUE"""),"VD018") -> VD018 | C37: =IFERROR(__xludf.DUMMYFUNCTION("""COMPUTED_VALUE"""),28.0) -> 28 | D37: =IFERROR(__xludf.DUMMYFUNCTION("""COMPUTED_VALUE"""),2149.73) -> 2149.73
A38: =IFERROR(__xludf.DUMMYFUNCTION("""COMPUTED_VALUE"""),"PR057") -> PR057 | B38: =IFERROR(__xludf.DUMMYFUNCTION("""COMPUTED_VALUE"""),"VD034") -> VD034 | C38: =IFERROR(__xludf.DUMMYFUNCTION("""COMPUTED_VALUE"""),9.0) -> 9 | D38: =IFERROR(__xludf.DUMMYFUNCTION("""COMPUTED_VALUE"""),906.19) -> 906.19
A39: =IFERROR(__xludf.DUMMYFUNCTION("""COMPUTED_VALUE"""),"PR004") -> PR004 | B39: =IFERROR(__xludf.DUMMYFUNCTION("""COMPUTED_VALUE"""),"VD024") -> VD024 | C39: =IFERROR(__xludf.DUMMYFUNCTION("""COMPUTED_VALUE"""),15.0) -> 15 | D39: =IFERROR(__xludf.DUMMYFUNCTION("""COMPUTED_VALUE"""),2610.0) -> 2610
A40: =IFERROR(__xludf.DUMMYFUNCTION("""COMPUTED_VALUE"""),"PR014") -> PR014 | B40: =IFERROR(__xludf.DUMMYFUNCTION("""COMPUTED_VALUE"""),"VD011") -> VD011 | C40: =IFERROR(__xludf.DUMMYFUNCTION("""COMPUTED_VALUE"""),12.0) -> 12 | D40: =IFERROR(__xludf.DUMMYFUNCTION("""COMPUTED_VALUE"""),560.2) -> 560.2
...

Sheet Datos Ventas Dashboard
A1: Productos | B1: Vendedor | C1: Cantidad | D1: Real Brasileño | E1: Peso Mexicano | F1: Sol Peruano | G1: Nombre | H1: Ciudad | I1: Región | J1: =Productos!B1 | K1: =Productos!C1 | L1: =Productos!D1 | M1: =Productos!E1 | N1: =Productos!F1
A2: =IFERROR(__xludf.DUMMYFUNCTION("query('Datos Ventas'!A2:K2000,""SELECT Col7, Col8, Col9, Col10"")"),"PR001") -> PR001 | B2: =IFERROR(__xludf.DUMMYFUNCTION("""COMPUTED_VALUE"""),"VD026") -> VD026 | C2: =IFERROR(__xludf.DUMMYFUNCTION("""COMPUTED_VALUE"""),27.0) -> 27 | D2: =IFERROR(__xludf.DUMMYFUNCTION("""COMPUTED_VALUE"""),1957.23) -> 1957.23 | E2: =IFERROR(__xludf.DUMMYFUNCTION("GOOGLEFINANCE(""Currency:BRLMXN"")*D2"),6648.7103099999995) -> 6648.7103 | F2: =IFERROR(__xludf.DUMMYFUNCTION("GOOGLEFINANCE(""Currency:BRLPEN"")*D2"),1283.1599879999999) -> 1283.16 | G2: {=_xlfn.XLOOKUP(B2,Vendedores!$A$2:$A$41,Vendedores!$B$2:$B$41,"No hay datos")} -> No hay datos | H2: {=_xlfn.XLOOKUP(B2,Vendedores!$A$2:$A$41,Vendedores!$C$2:$C$41,"No hay datos")} -> No hay datos | I2: {=_xlfn.XLOOKUP(B2,Vendedores!$A$2:$A$41,Vendedores!$D$2:$D$41,"No hay datos")} -> No hay datos | J2: {=_xlfn.XLOOKUP(A2,Productos!$A$2:$A$61,Productos!$B$2:$F$61)} -> #N/A
A3: =IFERROR(__xludf.DUMMYFUNCTION("""COMPUTED_VALUE"""),"PR058") -> PR058 | B3: =IFERROR(__xludf.DUMMYFUNCTION("""COMPUTED_VALUE"""),"VD037") -> VD037 | C3: =IFERROR(__xludf.DUMMYFUNCTION("""COMPUTED_VALUE"""),14.0) -> 14 | D3: =IFERROR(__xludf.DUMMYFUNCTION("""COMPUTED_VALUE"""),2872.8) -> 2872.8 | E3: =IFERROR(__xludf.DUMMYFUNCTION("GOOGLEFINANCE(""Currency:BRLMXN"")*D3"),9758.9016) -> 9758.9016 | F3: =IFERROR(__xludf.DUMMYFUNCTION("GOOGLEFINANCE(""Currency:BRLPEN"")*D3"),1883.40768) -> 1883.4077 | G3: {=_xlfn.XLOOKUP(B3,Vendedores!$A$2:$A$41,Vendedores!$B$2:$B$41,"No hay datos")} -> No hay datos | H3: {=_xlfn.XLOOKUP(B3,Vendedores!$A$2:$A$41,Vendedores!$C$2:$C$41,"No hay datos")} -> No hay datos | I3: {=_xlfn.XLOOKUP(B3,Vendedores!$A$2:$A$41,Vendedores!$D$2:$D$41,"No hay datos")} -> No hay datos | J3: {=_xlfn.XLOOKUP(A3,Productos!$A$2:$A$61,Productos!$B$2:$F$61)} -> #N/A
A4: =IFERROR(__xludf.DUMMYFUNCTION("""COMPUTED_VALUE"""),"PR020") -> PR020 | B4: =IFERROR(__xludf.DUMMYFUNCTION("""COMPUTED_VALUE"""),"VD034") -> VD034 | C4: =IFERROR(__xludf.DUMMYFUNCTION("""COMPUTED_VALUE"""),20.0) -> 20 | D4: =IFERROR(__xludf.DUMMYFUNCTION("""COMPUTED_VALUE"""),7137.62) -> 7137.62 | E4: =IFERROR(__xludf.DUMMYFUNCTION("GOOGLEFINANCE(""Currency:BRLMXN"")*D4"),24246.49514) -> 24246.495 | F4: =IFERROR(__xludf.DUMMYFUNCTION("GOOGLEFINANCE(""Currency:BRLPEN"")*D4"),4679.423672) -> 4679.4237 | G4: {=_xlfn.XLOOKUP(B4,Vendedores!$A$2:$A$41,Vendedores!$B$2:$B$41,"No hay datos")} -> No hay datos | H4: {=_xlfn.XLOOKUP(B4,Vendedores!$A$2:$A$41,Vendedores!$C$2:$C$41,"No hay datos")} -> No hay datos | I4: {=_xlfn.XLOOKUP(B4,Vendedores!$A$2:$A$41,Vendedores!$D$2:$D$41,"No hay datos")} -> No hay datos | J4: {=_xlfn.XLOOKUP(A4,Productos!$A$2:$A$61,Productos!$B$2:$F$61)} -> #N/A
A5: =IFERROR(__xludf.DUMMYFUNCTION("""COMPUTED_VALUE"""),"PR035") -> PR035 | B5: =IFERROR(__xludf.DUMMYFUNCTION("""COMPUTED_VALUE"""),"VD021") -> VD021 | C5: =IFERROR(__xludf.DUMMYFUNCTION("""COMPUTED_VALUE"""),24.0) -> 24 | D5: =IFERROR(__xludf.DUMMYFUNCTION("""COMPUTED_VALUE"""),2478.77) -> 2478.77 | E5: =IFERROR(__xludf.DUMMYFUNCTION("GOOGLEFINANCE(""Currency:BRLMXN"")*D5"),8420.38169) -> 8420.3817 | F5: =IFERROR(__xludf.DUMMYFUNCTION("GOOGLEFINANCE(""Currency:BRLPEN"")*D5"),1625.081612) -> 1625.0816 | G5: {=_xlfn.XLOOKUP(B5,Vendedores!$A$2:$A$41,Vendedores!$B$2:$B$41,"No hay datos")} -> No hay datos | H5: {=_xlfn.XLOOKUP(B5,Vendedores!$A$2:$A$41,Vendedores!$C$2:$C$41,"No hay datos")} -> No hay datos | I5: {=_xlfn.XLOOKUP(B5,Vendedores!$A$2:$A$41,Vendedores!$D$2:$D$41,"No hay datos")} -> No hay datos | J5: {=_xlfn.XLOOKUP(A5,Productos!$A$2:$A$61,Productos!$B$2:$F$61)} -> #N/A
A6: =IFERROR(__xludf.DUMMYFUNCTION("""COMPUTED_VALUE"""),"PR016") -> PR016 | B6: =IFERROR(__xludf.DUMMYFUNCTION("""COMPUTED_VALUE"""),"VD027") -> VD027 | C6: =IFERROR(__xludf.DUMMYFUNCTION("""COMPUTED_VALUE"""),10.0) -> 10 | D6: =IFERROR(__xludf.DUMMYFUNCTION("""COMPUTED_VALUE"""),303.03) -> 303.03 | E6: =IFERROR(__xludf.DUMMYFUNCTION("GOOGLEFINANCE(""Currency:BRLMXN"")*D6"),1029.3929099999998) -> 1029.3929 | F6: =IFERROR(__xludf.DUMMYFUNCTION("GOOGLEFINANCE(""Currency:BRLPEN"")*D6"),198.66646799999998) -> 198.66647 | G6: {=_xlfn.XLOOKUP(B6,Vendedores!$A$2:$A$41,Vendedores!$B$2:$B$41,"No hay datos")} -> No hay datos | H6: {=_xlfn.XLOOKUP(B6,Vendedores!$A$2:$A$41,Vendedores!$C$2:$C$41,"No hay datos")} -> No hay datos | I6: {=_xlfn.XLOOKUP(B6,Vendedores!$A$2:$A$41,Vendedores!$D$2:$D$41,"No hay datos")} -> No hay datos | J6: {=_xlfn.XLOOKUP(A6,Productos!$A$2:$A$61,Productos!$B$2:$F$61)} -> #N/A
A7: =IFERROR(__xludf.DUMMYFUNCTION("""COMPUTED_VALUE"""),"PR051") -> PR051 | B7: =IFERROR(__xludf.DUMMYFUNCTION("""COMPUTED_VALUE"""),"VD048") -> VD048 | C7: =IFERROR(__xludf.DUMMYFUNCTION("""COMPUTED_VALUE"""),18.0) -> 18 | D7: =IFERROR(__xludf.DUMMYFUNCTION("""COMPUTED_VALUE"""),704.72) -> 704.72 | E7: =IFERROR(__xludf.DUMMYFUNCTION("GOOGLEFINANCE(""Currency:BRLMXN"")*D7"),2393.93384) -> 2393.9338 | F7: =IFERROR(__xludf.DUMMYFUNCTION("GOOGLEFINANCE(""Currency:BRLPEN"")*D7"),462.014432) -> 462.01443 | G7: {=_xlfn.XLOOKUP(B7,Vendedores!$A$2:$A$41,Vendedores!$B$2:$B$41,"No hay datos")} -> No hay datos | H7: {=_xlfn.XLOOKUP(B7,Vendedores!$A$2:$A$41,Vendedores!$C$2:$C$41,"No hay datos")} -> No hay datos | I7: {=_xlfn.XLOOKUP(B7,Vendedores!$A$2:$A$41,Vendedores!$D$2:$D$41,"No hay datos")} -> No hay datos | J7: {=_xlfn.XLOOKUP(A7,Productos!$A$2:$A$61,Productos!$B$2:$F$61)} -> #N/A
A8: =IFERROR(__xludf.DUMMYFUNCTION("""COMPUTED_VALUE"""),"PR042") -> PR042 | B8: =IFERROR(__xludf.DUMMYFUNCTION("""COMPUTED_VALUE"""),"VD025") -> VD025 | C8: =IFERROR(__xludf.DUMMYFUNCTION("""COMPUTED_VALUE"""),27.0) -> 27 | D8: =IFERROR(__xludf.DUMMYFUNCTION("""COMPUTED_VALUE"""),1778.76) -> 1778.76 | E8: =IFERROR(__xludf.DUMMYFUNCTION("GOOGLEFINANCE(""Currency:BRLMXN"")*D8"),6042.447719999999) -> 6042.4477 | F8: =IFERROR(__xludf.DUMMYFUNCTION("GOOGLEFINANCE(""Currency:BRLPEN"")*D8"),1166.1550559999998) -> 1166.1551 | G8: {=_xlfn.XLOOKUP(B8,Vendedores!$A$2:$A$41,Vendedores!$B$2:$B$41,"No hay datos")} -> No hay datos | H8: {=_xlfn.XLOOKUP(B8,Vendedores!$A$2:$A$41,Vendedores!$C$2:$C$41,"No hay datos")} -> No hay datos | I8: {=_xlfn.XLOOKUP(B8,Vendedores!$A$2:$A$41,Vendedores!$D$2:$D$41,"No hay datos")} -> No hay datos | J8: {=_xlfn.XLOOKUP(A8,Productos!$A$2:$A$61,Productos!$B$2:$F$61)} -> #N/A
A9: =IFERROR(__xludf.DUMMYFUNCTION("""COMPUTED_VALUE"""),"PR050") -> PR050 | B9: =IFERROR(__xludf.DUMMYFUNCTION("""COMPUTED_VALUE"""),"VD037") -> VD037 | C9: =IFERROR(__xludf.DUMMYFUNCTION("""COMPUTED_VALUE"""),14.0) -> 14 | D9: =IFERROR(__xludf.DUMMYFUNCTION("""COMPUTED_VALUE"""),511.27) -> 511.27 | E9: =IFERROR(__xludf.DUMMYFUNCTION("GOOGLEFINANCE(""Currency:BRLMXN"")*D9"),1736.7841899999999) -> 1736.7842 | F9: =IFERROR(__xludf.DUMMYFUNCTION("GOOGLEFINANCE(""Currency:BRLPEN"")*D9"),335.188612) -> 335.18861 | G9: {=_xlfn.XLOOKUP(B9,Vendedores!$A$2:$A$41,Vendedores!$B$2:$B$41,"No hay datos")} -> No hay datos | H9: {=_xlfn.XLOOKUP(B9,Vendedores!$A$2:$A$41,Vendedores!$C$2:$C$41,"No hay datos")} -> No hay datos | I9: {=_xlfn.XLOOKUP(B9,Vendedores!$A$2:$A$41,Vendedores!$D$2:$D$41,"No hay datos")} -> No hay datos | J9: {=_xlfn.XLOOKUP(A9,Productos!$A$2:$A$61,Productos!$B$2:$F$61)} -> #N/A
A10: =IFERROR(__xludf.DUMMYFUNCTION("""COMPUTED_VALUE"""),"PR001") -> PR001 | B10: =IFERROR(__xludf.DUMMYFUNCTION("""COMPUTED_VALUE"""),"VD036") -> VD036 | C10: =IFERROR(__xludf.DUMMYFUNCTION("""COMPUTED_VALUE"""),12.0) -> 12 | D10: =IFERROR(__xludf.DUMMYFUNCTION("""COMPUTED_VALUE"""),901.51) -> 901.51 | E10: =IFERROR(__xludf.DUMMYFUNCTION("GOOGLEFINANCE(""Currency:BRLMXN"")*D10"),3062.4294699999996) -> 3062.4295 | F10: =IFERROR(__xludf.DUMMYFUNCTION("GOOGLEFINANCE(""Currency:BRLPEN"")*D10"),591.029956) -> 591.02996 | G10: {=_xlfn.XLOOKUP(B10,Vendedores!$A$2:$A$41,Vendedores!$B$2:$B$41,"No hay datos")} -> No hay datos | H10: {=_xlfn.XLOOKUP(B10,Vendedores!$A$2:$A$41,Vendedores!$C$2:$C$41,"No hay datos")} -> No hay datos | I10: {=_xlfn.XLOOKUP(B10,Vendedores!$A$2:$A$41,Vendedores!$D$2:$D$41,"No hay datos")} -> No hay datos | J10: {=_xlfn.XLOOKUP(A10,Productos!$A$2:$A$61,Productos!$B$2:$F$61)} -> #N/A
A11: =IFERROR(__xludf.DUMMYFUNCTION("""COMPUTED_VALUE"""),"PR059") -> PR059 | B11: =IFERROR(__xludf.DUMMYFUNCTION("""COMPUTED_VALUE"""),"VD049") -> VD049 | C11: =IFERROR(__xludf.DUMMYFUNCTION("""COMPUTED_VALUE"""),27.0) -> 27 | D11: =IFERROR(__xludf.DUMMYFUNCTION("""COMPUTED_VALUE"""),5783.4) -> 5783.4 | E11: =IFERROR(__xludf.DUMMYFUNCTION("GOOGLEFINANCE(""Currency:BRLMXN"")*D11"),19646.209799999997) -> 19646.21 | F11: =IFERROR(__xludf.DUMMYFUNCTION("GOOGLEFINANCE(""Currency:BRLPEN"")*D11"),3791.5970399999997) -> 3791.597 | G11: {=_xlfn.XLOOKUP(B11,Vendedores!$A$2:$A$41,Vendedores!$B$2:$B$41,"No hay datos")} -> No hay datos | H11: {=_xlfn.XLOOKUP(B11,Vendedores!$A$2:$A$41,Vendedores!$C$2:$C$41,"No hay datos")} -> No hay datos | I11: {=_xlfn.XLOOKUP(B11,Vendedores!$A$2:$A$41,Vendedores!$D$2:$D$41,"No hay datos")} -> No hay datos | J11: {=_xlfn.XLOOKUP(A11,Productos!$A$2:$A$61,Productos!$B$2:$F$61)} -> #N/A
A12: =IFERROR(__xludf.DUMMYFUNCTION("""COMPUTED_VALUE"""),"PR019") -> PR019 | B12: =IFERROR(__xludf.DUMMYFUNCTION("""COMPUTED_VALUE"""),"VD021") -> VD021 | C12: =IFERROR(__xludf.DUMMYFUNCTION("""COMPUTED_VALUE"""),15.0) -> 15 | D12: =IFERROR(__xludf.DUMMYFUNCTION("""COMPUTED_VALUE"""),845.81) -> 845.81 | E12: =IFERROR(__xludf.DUMMYFUNCTION("GOOGLEFINANCE(""Currency:BRLMXN"")*D12"),2873.2165699999996) -> 2873.2166 | F12: =IFERROR(__xludf.DUMMYFUNCTION("GOOGLEFINANCE(""Currency:BRLPEN"")*D12"),554.5130359999999) -> 554.51304 | G12: {=_xlfn.XLOOKUP(B12,Vendedores!$A$2:$A$41,Vendedores!$B$2:$B$41,"No hay datos")} -> No hay datos | H12: {=_xlfn.XLOOKUP(B12,Vendedores!$A$2:$A$41,Vendedores!$C$2:$C$41,"No hay datos")} -> No hay datos | I12: {=_xlfn.XLOOKUP(B12,Vendedores!$A$2:$A$41,Vendedores!$D$2:$D$41,"No hay datos")} -> No hay datos | J12: {=_xlfn.XLOOKUP(A12,Productos!$A$2:$A$61,Productos!$B$2:$F$61)} -> #N/A
A13: =IFERROR(__xludf.DUMMYFUNCTION("""COMPUTED_VALUE"""),"PR055") -> PR055 | B13: =IFERROR(__xludf.DUMMYFUNCTION("""COMPUTED_VALUE"""),"VD015") -> VD015 | C13: =IFERROR(__xludf.DUMMYFUNCTION("""COMPUTED_VALUE"""),18.0) -> 18 | D13: =IFERROR(__xludf.DUMMYFUNCTION("""COMPUTED_VALUE"""),1844.75) -> 1844.75 | E13: =IFERROR(__xludf.DUMMYFUNCTION("GOOGLEFINANCE(""Currency:BRLMXN"")*D13"),6266.61575) -> 6266.6157 | F13: =IFERROR(__xludf.DUMMYFUNCTION("GOOGLEFINANCE(""Currency:BRLPEN"")*D13"),1209.4180999999999) -> 1209.4181 | G13: {=_xlfn.XLOOKUP(B13,Vendedores!$A$2:$A$41,Vendedores!$B$2:$B$41,"No hay datos")} -> No hay datos | H13: {=_xlfn.XLOOKUP(B13,Vendedores!$A$2:$A$41,Vendedores!$C$2:$C$41,"No hay datos")} -> No hay datos | I13: {=_xlfn.XLOOKUP(B13,Vendedores!$A$2:$A$41,Vendedores!$D$2:$D$41,"No hay datos")} -> No hay datos | J13: {=_xlfn.XLOOKUP(A13,Productos!$A$2:$A$61,Productos!$B$2:$F$61)} -> #N/A
A14: =IFERROR(__xludf.DUMMYFUNCTION("""COMPUTED_VALUE"""),"PR052") -> PR052 | B14: =IFERROR(__xludf.DUMMYFUNCTION("""COMPUTED_VALUE"""),"VD012") -> VD012 | C14: =IFERROR(__xludf.DUMMYFUNCTION("""COMPUTED_VALUE"""),16.0) -> 16 | D14: =IFERROR(__xludf.DUMMYFUNCTION("""COMPUTED_VALUE"""),950.1) -> 950.1 | E14: =IFERROR(__xludf.DUMMYFUNCTION("GOOGLEFINANCE(""Currency:BRLMXN"")*D14"),3227.4897) -> 3227.4897 | F14: =IFERROR(__xludf.DUMMYFUNCTION("GOOGLEFINANCE(""Currency:BRLPEN"")*D14"),622.8855599999999) -> 622.88556 | G14: {=_xlfn.XLOOKUP(B14,Vendedores!$A$2:$A$41,Vendedores!$B$2:$B$41,"No hay datos")} -> No hay datos | H14: {=_xlfn.XLOOKUP(B14,Vendedores!$A$2:$A$41,Vendedores!$C$2:$C$41,"No hay datos")} -> No hay datos | I14: {=_xlfn.XLOOKUP(B14,Vendedores!$A$2:$A$41,Vendedores!$D$2:$D$41,"No hay datos")} -> No hay datos | J14: {=_xlfn.XLOOKUP(A14,Productos!$A$2:$A$61,Productos!$B$2:$F$61)} -> #N/A
A15: =IFERROR(__xludf.DUMMYFUNCTION("""COMPUTED_VALUE"""),"PR052") -> PR052 | B15: =IFERROR(__xludf.DUMMYFUNCTION("""COMPUTED_VALUE"""),"VD043") -> VD043 | C15: =IFERROR(__xludf.DUMMYFUNCTION("""COMPUTED_VALUE"""),9.0) -> 9 | D15: =IFERROR(__xludf.DUMMYFUNCTION("""COMPUTED_VALUE"""),511.97) -> 511.97 | E15: =IFERROR(__xludf.DUMMYFUNCTION("GOOGLEFINANCE(""Currency:BRLMXN"")*D15"),1739.16209) -> 1739.1621 | F15: =IFERROR(__xludf.DUMMYFUNCTION("GOOGLEFINANCE(""Currency:BRLPEN"")*D15"),335.647532) -> 335.64753 | G15: {=_xlfn.XLOOKUP(B15,Vendedores!$A$2:$A$41,Vendedores!$B$2:$B$41,"No hay datos")} -> No hay datos | H15: {=_xlfn.XLOOKUP(B15,Vendedores!$A$2:$A$41,Vendedores!$C$2:$C$41,"No hay datos")} -> No hay datos | I15: {=_xlfn.XLOOKUP(B15,Vendedores!$A$2:$A$41,Vendedores!$D$2:$D$41,"No hay datos")} -> No hay datos | J15: {=_xlfn.XLOOKUP(A15,Productos!$A$2:$A$61,Productos!$B$2:$F$61)} -> #N/A
