Workbook

Sheet Datos Ventas
A1: =IFERROR(__xludf.DUMMYFUNCTION("importdata(""https://drive.google.com/uc?export=download&id=1U1AR8u12BH41vb1Uvb31WaPc4KTs4qQo&v=2"","";"")"),"Empresa") -> Empresa | B1: =IFERROR(__xludf.DUMMYFUNCTION("""COMPUTED_VALUE"""),"Número de Documento") -> Número de Documento | C1: =IFERROR(__xludf.DUMMYFUNCTION("""COMPUTED_VALUE"""),"Año Fiscal") -> Año Fiscal | D1: =IFERROR(__xludf.DUMMYFUNCTION("""COMPUTED_VALUE"""),"Fecha") -> Fecha | E1: =IFERROR(__xludf.DUMMYFUNCTION("""COMPUTED_VALUE"""),"Tipo de Documento") -> Tipo de Documento | F1: =IFERROR(__xludf.DUMMYFUNCTION("""COMPUTED_VALUE"""),"Número de Artículo") -> Número de Artículo | G1: =IFERROR(__xludf.DUMMYFUNCTION("""COMPUTED_VALUE"""),"Material") -> Material | H1: =IFERROR(__xludf.DUMMYFUNCTION("""COMPUTED_VALUE"""),"Vendedor") -> Vendedor | I1: =IFERROR(__xludf.DUMMYFUNCTION("""COMPUTED_VALUE"""),"Cantidad") -> Cantidad | J1: =IFERROR(__xludf.DUMMYFUNCTION("""COMPUTED_VALUE"""),"Valor en Moneda Local") -> Valor en Moneda Local | K1: =IFERROR(__xludf.DUMMYFUNCTION("""COMPUTED_VALUE"""),"Valor en Moneda Extranjera") -> Valor en Moneda Extranjera
A2: =IFERROR(__xludf.DUMMYFUNCTION("""COMPUTED_VALUE"""),1000.0) -> 1000 | B2: =IFERROR(__xludf.DUMMYFUNCTION("""COMPUTED_VALUE"""),183456.0) -> 183456 | C2: =IFERROR(__xludf.DUMMYFUNCTION("""COMPUTED_VALUE"""),2026.0) -> 2026 | D2: =IFERROR(__xludf.DUMMYFUNCTION("""COMPUTED_VALUE"""),46387.0) -> 46387 | E2: =IFERROR(__xludf.DUMMYFUNCTION("""COMPUTED_VALUE"""),"VF") -> VF | F2: =IFERROR(__xludf.DUMMYFUNCTION("""COMPUTED_VALUE"""),1.0) -> 1 | G2: =IFERROR(__xludf.DUMMYFUNCTION("""COMPUTED_VALUE"""),"PR001") -> PR001 | H2: =IFERROR(__xludf.DUMMYFUNCTION("""COMPUTED_VALUE"""),"VD026") -> VD026 | I2: =IFERROR(__xludf.DUMMYFUNCTION("""COMPUTED_VALUE"""),27.0) -> 27 | J2: =IFERROR(__xludf.DUMMYFUNCTION("""COMPUTED_VALUE"""),1957.23) -> 1957.23 | K2: =IFERROR(__xludf.DUMMYFUNCTION("""COMPUTED_VALUE"""),1957.23) -> 1957.23
A3: =IFERROR(__xludf.DUMMYFUNCTION("""COMPUTED_VALUE"""),1000.0) -> 1000 | B3: =IFERROR(__xludf.DUMMYFUNCTION("""COMPUTED_VALUE"""),183456.0) -> 183456 | C3: =IFERROR(__xludf.DUMMYFUNCTION("""COMPUTED_VALUE"""),2026.0) -> 2026 | D3: =IFERROR(__xludf.DUMMYFUNCTION("""COMPUTED_VALUE"""),46387.0) -> 46387 | E3: =IFERROR(__xludf.DUMMYFUNCTION("""COMPUTED_VALUE"""),"VF") -> VF | F3: =IFERROR(__xludf.DUMMYFUNCTION("""COMPUTED_VALUE"""),2.0) -> 2 | G3: =IFERROR(__xludf.DUMMYFUNCTION("""COMPUTED_VALUE"""),"PR058") -> PR058 | H3: =IFERROR(__xludf.DUMMYFUNCTION("""COMPUTED_VALUE"""),"VD037") -> VD037 | I3: =IFERROR(__xludf.DUMMYFUNCTION("""COMPUTED_VALUE"""),14.0) -> 14 | J3: =IFERROR(__xludf.DUMMYFUNCTION("""COMPUTED_VALUE"""),2872.8) -> 2872.8 | K3: =IFERROR(__xludf.DUMMYFUNCTION("""COMPUTED_VALUE"""),2872.8) -> 2872.8
A4: =IFERROR(__xludf.DUMMYFUNCTION("""COMPUTED_VALUE"""),1000.0) -> 1000 | B4: =IFERROR(__xludf.DUMMYFUNCTION("""COMPUTED_VALUE"""),183457.0) -> 183457 | C4: =IFERROR(__xludf.DUMMYFUNCTION("""COMPUTED_VALUE"""),2026.0) -> 2026 | D4: =IFERROR(__xludf.DUMMYFUNCTION("""COMPUTED_VALUE"""),46387.0) -> 46387 | E4: =IFERROR(__xludf.DUMMYFUNCTION("""COMPUTED_VALUE"""),"VF") -> VF | F4: =IFERROR(__xludf.DUMMYFUNCTION("""COMPUTED_VALUE"""),1.0) -> 1 | G4: =IFERROR(__xludf.DUMMYFUNCTION("""COMPUTED_VALUE"""),"PR020") -> PR020 | H4: =IFERROR(__xludf.DUMMYFUNCTION("""COMPUTED_VALUE"""),"VD034") -> VD034 | I4: =IFERROR(__xludf.DUMMYFUNCTION("""COMPUTED_VALUE"""),20.0) -> 20 | J4: =IFERROR(__xludf.DUMMYFUNCTION("""COMPUTED_VALUE"""),7137.62) -> 7137.62 | K4: =IFERROR(__xludf.DUMMYFUNCTION("""COMPUTED_VALUE"""),7137.62) -> 7137.62
A5: =IFERROR(__xludf.DUMMYFUNCTION("""COMPUTED_VALUE"""),1000.0) -> 1000 | B5: =IFERROR(__xludf.DUMMYFUNCTION("""COMPUTED_VALUE"""),183458.0) -> 183458 | C5: =IFERROR(__xludf.DUMMYFUNCTION("""COMPUTED_VALUE"""),2026.0) -> 2026 | D5: =IFERROR(__xludf.DUMMYFUNCTION("""COMPUTED_VALUE"""),46387.0) -> 46387 | E5: =IFERROR(__xludf.DUMMYFUNCTION("""COMPUTED_VALUE"""),"VF") -> VF | F5: =IFERROR(__xludf.DUMMYFUNCTION("""COMPUTED_VALUE"""),1.0) -> 1 | G5: =IFERROR(__xludf.DUMMYFUNCTION("""COMPUTED_VALUE"""),"PR035") -> PR035 | H5: =IFERROR(__xludf.DUMMYFUNCTION("""COMPUTED_VALUE"""),"VD021") -> VD021 | I5: =IFERROR(__xludf.DUMMYFUNCTION("""COMPUTED_VALUE"""),24.0) -> 24 | J5: =IFERROR(__xludf.DUMMYFUNCTION("""COMPUTED_VALUE"""),2478.77) -> 2478.77 | K5: =IFERROR(__xludf.DUMMYFUNCTION("""COMPUTED_VALUE"""),2478.77) -> 2478.77
A6: =IFERROR(__xludf.DUMMYFUNCTION("""COMPUTED_VALUE"""),1000.0) -> 1000 | B6: =IFERROR(__xludf.DUMMYFUNCTION("""COMPUTED_VALUE"""),183459.0) -> 183459 | C6: =IFERROR(__xludf.DUMMYFUNCTION("""COMPUTED_VALUE"""),2026.0) -> 2026 | D6: =IFERROR(__xludf.DUMMYFUNCTION("""COMPUTED_VALUE"""),46387.0) -> 46387 | E6: =IFERROR(__xludf.DUMMYFUNCTION("""COMPUTED_VALUE"""),"VF") -> VF | F6: =IFERROR(__xludf.DUMMYFUNCTION("""COMPUTED_VALUE"""),1.0) -> 1 | G6: =IFERROR(__xludf.DUMMYFUNCTION("""COMPUTED_VALUE"""),"PR016") -> PR016 | H6: =IFERROR(__xludf.DUMMYFUNCTION("""COMPUTED_VALUE"""),"VD027") -> VD027 | I6: =IFERROR(__xludf.DUMMYFUNCTION("""COMPUTED_VALUE"""),10.0) -> 10 | J6: =IFERROR(__xludf.DUMMYFUNCTION("""COMPUTED_VALUE"""),303.03) -> 303.03 | K6: =IFERROR(__xludf.DUMMYFUNCTION("""COMPUTED_VALUE"""),303.03) -> 303.03
A7: =IFERROR(__xludf.DUMMYFUNCTION("""COMPUTED_VALUE"""),1000.0) -> 1000 | B7: =IFERROR(__xludf.DUMMYFUNCTION("""COMPUTED_VALUE"""),183460.0) -> 183460 | C7: =IFERROR(__xludf.DUMMYFUNCTION("""COMPUTED_VALUE"""),2026.0) -> 2026 | D7: =IFERROR(__xludf.DUMMYFUNCTION("""COMPUTED_VALUE"""),46387.0) -> 46387 | E7: =IFERROR(__xludf.DUMMYFUNCTION("""COMPUTED_VALUE"""),"VF") -> VF | F7: =IFERROR(__xludf.DUMMYFUNCTION("""COMPUTED_VALUE"""),1.0) -> 1 | G7: =IFERROR(__xludf.DUMMYFUNCTION("""COMPUTED_VALUE"""),"PR051") -> PR051 | H7: =IFERROR(__xludf.DUMMYFUNCTION("""COMPUTED_VALUE"""),"VD048") -> VD048 | I7: =IFERROR(__xludf.DUMMYFUNCTION("""COMPUTED_VALUE"""),18.0) -> 18 | J7: =IFERROR(__xludf.DUMMYFUNCTION("""COMPUTED_VALUE"""),704.72) -> 704.72 | K7: =IFERROR(__xludf.DUMMYFUNCTION("""COMPUTED_VALUE"""),704.72) -> 704.72
A8: =IFERROR(__xludf.DUMMYFUNCTION("""COMPUTED_VALUE"""),1000.0) -> 1000 | B8: =IFERROR(__xludf.DUMMYFUNCTION("""COMPUTED_VALUE"""),183461.0) -> 183461 | C8: =IFERROR(__xludf.DUMMYFUNCTION("""COMPUTED_VALUE"""),2026.0) -> 2026 | D8: =IFERROR(__xludf.DUMMYFUNCTION("""COMPUTED_VALUE"""),46387.0) -> 46387 | E8: =IFERROR(__xludf.DUMMYFUNCTION("""COMPUTED_VALUE"""),"VF") -> VF | F8: =IFERROR(__xludf.DUMMYFUNCTION("""COMPUTED_VALUE"""),1.0) -> 1 | G8: =IFERROR(__xludf.DUMMYFUNCTION("""COMPUTED_VALUE"""),"PR042") -> PR042 | H8: =IFERROR(__xludf.DUMMYFUNCTION("""COMPUTED_VALUE"""),"VD025") -> VD025 | I8: =IFERROR(__xludf.DUMMYFUNCTION("""COMPUTED_VALUE"""),27.0) -> 27 | J8: =IFERROR(__xludf.DUMMYFUNCTION("""COMPUTED_VALUE"""),1778.76) -> 1778.76 | K8: =IFERROR(__xludf.DUMMYFUNCTION("""COMPUTED_VALUE"""),1778.76) -> 1778.76
A9: =IFERROR(__xludf.DUMMYFUNCTION("""COMPUTED_VALUE"""),1000.0) -> 1000 | B9: =IFERROR(__xludf.DUMMYFUNCTION("""COMPUTED_VALUE"""),183462.0) -> 183462 | C9: =IFERROR(__xludf.DUMMYFUNCTION("""COMPUTED_VALUE"""),2026.0) -> 2026 | D9: =IFERROR(__xludf.DUMMYFUNCTION("""COMPUTED_VALUE"""),46387.0) -> 46387 | E9: =IFERROR(__xludf.DUMMYFUNCTION("""COMPUTED_VALUE"""),"VF") -> VF | F9: =IFERROR(__xludf.DUMMYFUNCTION("""COMPUTED_VALUE"""),1.0) -> 1 | G9: =IFERROR(__xludf.DUMMYFUNCTION("""COMPUTED_VALUE"""),"PR050") -> PR050 | H9: =IFERROR(__xludf.DUMMYFUNCTION("""COMPUTED_VALUE"""),"VD037") -> VD037 | I9: =IFERROR(__xludf.DUMMYFUNCTION("""COMPUTED_VALUE"""),14.0) -> 14 | J9: =IFERROR(__xludf.DUMMYFUNCTION("""COMPUTED_VALUE"""),511.27) -> 511.27 | K9: =IFERROR(__xludf.DUMMYFUNCTION("""COMPUTED_VALUE"""),511.27) -> 511.27
A10: =IFERROR(__xludf.DUMMYFUNCTION("""COMPUTED_VALUE"""),1000.0) -> 1000 | B10: =IFERROR(__xludf.DUMMYFUNCTION("""COMPUTED_VALUE"""),183463.0) -> 183463 | C10: =IFERROR(__xludf.DUMMYFUNCTION("""COMPUTED_VALUE"""),2026.0) -> 2026 | D10: =IFERROR(__xludf.DUMMYFUNCTION("""COMPUTED_VALUE"""),46387.0) -> 46387 | E10: =IFERROR(__xludf.DUMMYFUNCTION("""COMPUTED_VALUE"""),"VF") -> VF | F10: =IFERROR(__xludf.DUMMYFUNCTION("""COMPUTED_VALUE"""),1.0) -> 1 | G10: =IFERROR(__xludf.DUMMYFUNCTION("""COMPUTED_VALUE"""),"PR001") -> PR001 | H10: =IFERROR(__xludf.DUMMYFUNCTION("""COMPUTED_VALUE"""),"VD036") -> VD036 | I10: =IFERROR(__xludf.DUMMYFUNCTION("""COMPUTED_VALUE"""),12.0) -> 12 | J10: =IFERROR(__xludf.DUMMYFUNCTION("""COMPUTED_VALUE"""),901.51) -> 901.51 | K10: =IFERROR(__xludf.DUMMYFUNCTION("""COMPUTED_VALUE"""),901.51) -> 901.51
A11: =IFERROR(__xludf.DUMMYFUNCTION("""COMPUTED_VALUE"""),1000.0) -> 1000 | B11: =IFERROR(__xludf.DUMMYFUNCTION("""COMPUTED_VALUE"""),183464.0) -> 183464 | C11: =IFERROR(__xludf.DUMMYFUNCTION("""COMPUTED_VALUE"""),2026.0) -> 2026 | D11: =IFERROR(__xludf.DUMMYFUNCTION("""COMPUTED_VALUE"""),46387.0) -> 46387 | E11: =IFERROR(__xludf.DUMMYFUNCTION("""COMPUTED_VALUE"""),"VF") -> VF | F11: =IFERROR(__xludf.DUMMYFUNCTION("""COMPUTED_VALUE"""),1.0) -> 1 | G11: =IFERROR(__xludf.DUMMYFUNCTION("""COMPUTED_VALUE"""),"PR059") -> PR059 | H11: =IFERROR(__xludf.DUMMYFUNCTION("""COMPUTED_VALUE"""),"VD049") -> VD049 | I11: =IFERROR(__xludf.DUMMYFUNCTION("""COMPUTED_VALUE"""),27.0) -> 27 | J11: =IFERROR(__xludf.DUMMYFUNCTION("""COMPUTED_VALUE"""),5783.4) -> 5783.4 | K11: =IFERROR(__xludf.DUMMYFUNCTION("""COMPUTED_VALUE"""),5783.4) -> 5783.4
A12: =IFERROR(__xludf.DUMMYFUNCTION("""COMPUTED_VALUE"""),1000.0) -> 1000 | B12: =IFERROR(__xludf.DUMMYFUNCTION("""COMPUTED_VALUE"""),183465.0) -> 183465 | C12: =IFERROR(__xludf.DUMMYFUNCTION("""COMPUTED_VALUE"""),2026.0) -> 2026 | D12: =IFERROR(__xludf.DUMMYFUNCTION("""COMPUTED_VALUE"""),46387.0) -> 46387 | E12: =IFERROR(__xludf.DUMMYFUNCTION("""COMPUTED_VALUE"""),"VF") -> VF | F12: =IFERROR(__xludf.DUMMYFUNCTION("""COMPUTED_VALUE"""),1.0) -> 1 | G12: =IFERROR(__xludf.DUMMYFUNCTION("""COMPUTED_VALUE"""),"PR019") -> PR019 | H12: =IFERROR(__xludf.DUMMYFUNCTION("""COMPUTED_VALUE"""),"VD021") -> VD021 | I12: =IFERROR(__xludf.DUMMYFUNCTION("""COMPUTED_VALUE"""),15.0) -> 15 | J12: =IFERROR(__xludf.DUMMYFUNCTION("""COMPUTED_VALUE"""),845.81) -> 845.81 | K12: =IFERROR(__xludf.DUMMYFUNCTION("""COMPUTED_VALUE"""),845.81) -> 845.81
A13: =IFERROR(__xludf.DUMMYFUNCTION("""COMPUTED_VALUE"""),1000.0) -> 1000 | B13: =IFERROR(__xludf.DUMMYFUNCTION("""COMPUTED_VALUE"""),183466.0) -> 183466 | C13: =IFERROR(__xludf.DUMMYFUNCTION("""COMPUTED_VALUE"""),2026.0) -> 2026 | D13: =IFERROR(__xludf.DUMMYFUNCTION("""COMPUTED_VALUE"""),46387.0) -> 46387 | E13: =IFERROR(__xludf.DUMMYFUNCTION("""COMPUTED_VALUE"""),"VF") -> VF | F13: =IFERROR(__xludf.DUMMYFUNCTION("""COMPUTED_VALUE"""),1.0) -> 1 | G13: =IFERROR(__xludf.DUMMYFUNCTION("""COMPUTED_VALUE"""),"PR055") -> PR055 | H13: =IFERROR(__xludf.DUMMYFUNCTION("""COMPUTED_VALUE"""),"VD015") -> VD015 | I13: =IFERROR(__xludf.DUMMYFUNCTION("""COMPUTED_VALUE"""),18.0) -> 18 | J13: =IFERROR(__xludf.DUMMYFUNCTION("""COMPUTED_VALUE"""),1844.75) -> 1844.75 | K13: =IFERROR(__xludf.DUMMYFUNCTION("""COMPUTED_VALUE"""),1844.75) -> 1844.75
A14: =IFERROR(__xludf.DUMMYFUNCTION("""COMPUTED_VALUE"""),1000.0) -> 1000 | B14: =IFERROR(__xludf.DUMMYFUNCTION("""COMPUTED_VALUE"""),183466.0) -> 183466 | C14: =IFERROR(__xludf.DUMMYFUNCTION("""COMPUTED_VALUE"""),2026.0) -> 2026 | D14: =IFERROR(__xludf.DUMMYFUNCTION("""COMPUTED_VALUE"""),46387.0) -> 46387 | E14: =IFERROR(__xludf.DUMMYFUNCTION("""COMPUTED_VALUE"""),"VF") -> VF | F14: =IFERROR(__xludf.DUMMYFUNCTION("""COMPUTED_VALUE"""),2.0) -> 2 | G14: =IFERROR(__xludf.DUMMYFUNCTION("""COMPUTED_VALUE"""),"PR052") -> PR052 | H14: =IFERROR(__xludf.DUMMYFUNCTION("""COMPUTED_VALUE"""),"VD012") -> VD012 | I14: =IFERROR(__xludf.DUMMYFUNCTION("""COMPUTED_VALUE"""),16.0) -> 16 | J14: =IFERROR(__xludf.DUMMYFUNCTION("""COMPUTED_VALUE"""),950.1) -> 950.1 | K14: =IFERROR(__xludf.DUMMYFUNCTION("""COMPUTED_VALUE"""),950.1) -> 950.1
A15: =IFERROR(__xludf.DUMMYFUNCTION("""COMPUTED_VALUE"""),1000.0) -> 1000 | B15: =IFERROR(__xludf.DUMMYFUNCTION("""COMPUTED_VALUE"""),183466.0) -> 183466 | C15: =IFERROR(__xludf.DUMMYFUNCTION("""COMPUTED_VALUE"""),2026.0) -> 2026 | D15: =IFERROR(__xludf.DUMMYFUNCTION("""COMPUTED_VALUE"""),46387.0) -> 46387 | E15: =IFERROR(__xludf.DUMMYFUNCTION("""COMPUTED_VALUE"""),"VF") -> VF | F15: =IFERROR(__xludf.DUMMYFUNCTION("""COMPUTED_VALUE"""),3.0) -> 3 | G15: =IFERROR(__xludf.DUMMYFUNCTION("""COMPUTED_VALUE"""),"PR052") -> PR052 | H15: =IFERROR(__xludf.DUMMYFUNCTION("""COMPUTED_VALUE"""),"VD043") -> VD043 | I15: =IFERROR(__xludf.DUMMYFUNCTION("""COMPUTED_VALUE"""),9.0) -> 9 | J15: =IFERROR(__xludf.DUMMYFUNCTION("""COMPUTED_VALUE"""),511.97) -> 511.97 | K15: =IFERROR(__xludf.DUMMYFUNCTION("""COMPUTED_VALUE"""),511.97) -> 511.97
A16: =IFERROR(__xludf.DUMMYFUNCTION("""COMPUTED_VALUE"""),1000.0) -> 1000 | B16: =IFERROR(__xludf.DUMMYFUNCTION("""COMPUTED_VALUE"""),183467.0) -> 183467 | C16: =IFERROR(__xludf.DUMMYFUNCTION("""COMPUTED_VALUE"""),2026.0) -> 2026 | D16: =IFERROR(__xludf.DUMMYFUNCTION("""COMPUTED_VALUE"""),46386.0) -> 46386 | E16: =IFERROR(__xludf.DUMMYFUNCTION("""COMPUTED_VALUE"""),"VF") -> VF | F16: =IFERROR(__xludf.DUMMYFUNCTION("""COMPUTED_VALUE"""),1.0) -> 1 | G16: =IFERROR(__xludf.DUMMYFUNCTION("""COMPUTED_VALUE"""),"PR014") -> PR014 | H16: =IFERROR(__xludf.DUMMYFUNCTION("""COMPUTED_VALUE"""),"VD020") -> VD020 | I16: =IFERROR(__xludf.DUMMYFUNCTION("""COMPUTED_VALUE"""),9.0) -> 9 | J16: =IFERROR(__xludf.DUMMYFUNCTION("""COMPUTED_VALUE"""),420.15) -> 420.15 | K16: =IFERROR(__xludf.DUMMYFUNCTION("""COMPUTED_VALUE"""),420.15) -> 420.15
A17: =IFERROR(__xludf.DUMMYFUNCTION("""COMPUTED_VALUE"""),1000.0) -> 1000 | B17: =IFERROR(__xludf.DUMMYFUNCTION("""COMPUTED_VALUE"""),183468.0) -> 183468 | C17: =IFERROR(__xludf.DUMMYFUNCTION("""COMPUTED_VALUE"""),2026.0) -> 2026 | D17: =IFERROR(__xludf.DUMMYFUNCTION("""COMPUTED_VALUE"""),46386.0) -> 46386 | E17: =IFERROR(__xludf.DUMMYFUNCTION("""COMPUTED_VALUE"""),"VF") -> VF | F17: =IFERROR(__xludf.DUMMYFUNCTION("""COMPUTED_VALUE"""),1.0) -> 1 | G17: =IFERROR(__xludf.DUMMYFUNCTION("""COMPUTED_VALUE"""),"PR055") -> PR055 | H17: =IFERROR(__xludf.DUMMYFUNCTION("""COMPUTED_VALUE"""),"VD019") -> VD019 | I17: =IFERROR(__xludf.DUMMYFUNCTION("""COMPUTED_VALUE"""),9.0) -> 9 | J17: =IFERROR(__xludf.DUMMYFUNCTION("""COMPUTED_VALUE"""),890.01) -> 890.01 | K17: =IFERROR(__xludf.DUMMYFUNCTION("""COMPUTED_VALUE"""),890.01) -> 890.01
A18: =IFERROR(__xludf.DUMMYFUNCTION("""COMPUTED_VALUE"""),1000.0) -> 1000 | B18: =IFERROR(__xludf.DUMMYFUNCTION("""COMPUTED_VALUE"""),183469.0) -> 183469 | C18: =IFERROR(__xludf.DUMMYFUNCTION("""COMPUTED_VALUE"""),2026.0) -> 2026 | D18: =IFERROR(__xludf.DUMMYFUNCTION("""COMPUTED_VALUE"""),46386.0) -> 46386 | E18: =IFERROR(__xludf.DUMMYFUNCTION("""COMPUTED_VALUE"""),"VF") -> VF | F18: =IFERROR(__xludf.DUMMYFUNCTION("""COMPUTED_VALUE"""),1.0) -> 1 | G18: =IFERROR(__xludf.DUMMYFUNCTION("""COMPUTED_VALUE"""),"PR045") -> PR045 | H18: =IFERROR(__xludf.DUMMYFUNCTION("""COMPUTED_VALUE"""),"VD041") -> VD041 | I18: =IFERROR(__xludf.DUMMYFUNCTION("""COMPUTED_VALUE"""),14.0) -> 14 | J18: =IFERROR(__xludf.DUMMYFUNCTION("""COMPUTED_VALUE"""),1157.1) -> 1157.1 | K18: =IFERROR(__xludf.DUMMYFUNCTION("""COMPUTED_VALUE"""),1157.1) -> 1157.1
A19: =IFERROR(__xludf.DUMMYFUNCTION("""COMPUTED_VALUE"""),1000.0) -> 1000 | B19: =IFERROR(__xludf.DUMMYFUNCTION("""COMPUTED_VALUE"""),183470.0) -> 183470 | C19: =IFERROR(__xludf.DUMMYFUNCTION("""COMPUTED_VALUE"""),2026.0) -> 2026 | D19: =IFERROR(__xludf.DUMMYFUNCTION("""COMPUTED_VALUE"""),46386.0) -> 46386 | E19: =IFERROR(__xludf.DUMMYFUNCTION("""COMPUTED_VALUE"""),"VF") -> VF | F19: =IFERROR(__xludf.DUMMYFUNCTION("""COMPUTED_VALUE"""),1.0) -> 1 | G19: =IFERROR(__xludf.DUMMYFUNCTION("""COMPUTED_VALUE"""),"PR053") -> PR053 | H19: =IFERROR(__xludf.DUMMYFUNCTION("""COMPUTED_VALUE"""),"VD013") -> VD013 | I19: =IFERROR(__xludf.DUMMYFUNCTION("""COMPUTED_VALUE"""),9.0) -> 9 | J19: =IFERROR(__xludf.DUMMYFUNCTION("""COMPUTED_VALUE"""),511.97) -> 511.97 | K19: =IFERROR(__xludf.DUMMYFUNCTION("""COMPUTED_VALUE"""),511.97) -> 511.97
A20: =IFERROR(__xludf.DUMMYFUNCTION("""COMPUTED_VALUE"""),1000.0) -> 1000 | B20: =IFERROR(__xludf.DUMMYFUNCTION("""COMPUTED_VALUE"""),183471.0) -> 183471 | C20: =IFERROR(__xludf.DUMMYFUNCTION("""COMPUTED_VALUE"""),2026.0) -> 2026 | D20: =IFERROR(__xludf.DUMMYFUNCTION("""COMPUTED_VALUE"""),46386.0) -> 46386 | E20: =IFERROR(__xludf.DUMMYFUNCTION("""COMPUTED_VALUE"""),"VF") -> VF | F20: =IFERROR(__xludf.DUMMYFUNCTION("""COMPUTED_VALUE"""),1.0) -> 1 | G20: =IFERROR(__xludf.DUMMYFUNCTION("""COMPUTED_VALUE"""),"PR054") -> PR054 | H20: =IFERROR(__xludf.DUMMYFUNCTION("""COMPUTED_VALUE"""),"VD028") -> VD028 | I20: =IFERROR(__xludf.DUMMYFUNCTION("""COMPUTED_VALUE"""),9.0) -> 9 | J20: =IFERROR(__xludf.DUMMYFUNCTION("""COMPUTED_VALUE"""),538.92) -> 538.92 | K20: =IFERROR(__xludf.DUMMYFUNCTION("""COMPUTED_VALUE"""),538.92) -> 538.92
A21: =IFERROR(__xludf.DUMMYFUNCTION("""COMPUTED_VALUE"""),2000.0) -> 2000 | B21: =IFERROR(__xludf.DUMMYFUNCTION("""COMPUTED_VALUE"""),183472.0) -> 183472 | C21: =IFERROR(__xludf.DUMMYFUNCTION("""COMPUTED_VALUE"""),2026.0) -> 2026 | D21: =IFERROR(__xludf.DUMMYFUNCTION("""COMPUTED_VALUE"""),46386.0) -> 46386 | E21: =IFERROR(__xludf.DUMMYFUNCTION("""COMPUTED_VALUE"""),"VF") -> VF | F21: =IFERROR(__xludf.DUMMYFUNCTION("""COMPUTED_VALUE"""),1.0) -> 1 | G21: =IFERROR(__xludf.DUMMYFUNCTION("""COMPUTED_VALUE"""),"PR020") -> PR020 | H21: =IFERROR(__xludf.DUMMYFUNCTION("""COMPUTED_VALUE"""),"VD047") -> VD047 | I21: =IFERROR(__xludf.DUMMYFUNCTION("""COMPUTED_VALUE"""),27.0) -> 27 | J21: =IFERROR(__xludf.DUMMYFUNCTION("""COMPUTED_VALUE"""),8907.03) -> 8907.03 | K21: =IFERROR(__xludf.DUMMYFUNCTION("""COMPUTED_VALUE"""),8907.03) -> 8907.03
A22: =IFERROR(__xludf.DUMMYFUNCTION("""COMPUTED_VALUE"""),1000.0) -> 1000 | B22: =IFERROR(__xludf.DUMMYFUNCTION("""COMPUTED_VALUE"""),183472.0) -> 183472 | C22: =IFERROR(__xludf.DUMMYFUNCTION("""COMPUTED_VALUE"""),2026.0) -> 2026 | D22: =IFERROR(__xludf.DUMMYFUNCTION("""COMPUTED_VALUE"""),46386.0) -> 46386 | E22: =IFERROR(__xludf.DUMMYFUNCTION("""COMPUTED_VALUE"""),"VF") -> VF | F22: =IFERROR(__xludf.DUMMYFUNCTION("""COMPUTED_VALUE"""),2.0) -> 2 | G22: =IFERROR(__xludf.DUMMYFUNCTION("""COMPUTED_VALUE"""),"PR047") -> PR047 | H22: =IFERROR(__xludf.DUMMYFUNCTION("""COMPUTED_VALUE"""),"VD017") -> VD017 | I22: =IFERROR(__xludf.DUMMYFUNCTION("""COMPUTED_VALUE"""),12.0) -> 12 | J22: =IFERROR(__xludf.DUMMYFUNCTION("""COMPUTED_VALUE"""),4174.56) -> 4174.56 | K22: =IFERROR(__xludf.DUMMYFUNCTION("""COMPUTED_VALUE"""),4174.56) -> 4174.56
A23: =IFERROR(__xludf.DUMMYFUNCTION("""COMPUTED_VALUE"""),2000.0) -> 2000 | B23: =IFERROR(__xludf.DUMMYFUNCTION("""COMPUTED_VALUE"""),183473.0) -> 183473 | C23: =IFERROR(__xludf.DUMMYFUNCTION("""COMPUTED_VALUE"""),2026.0) -> 2026 | D23: =IFERROR(__xludf.DUMMYFUNCTION("""COMPUTED_VALUE"""),46386.0) -> 46386 | E23: =IFERROR(__xludf.DUMMYFUNCTION("""COMPUTED_VALUE"""),"VF") -> VF | F23: =IFERROR(__xludf.DUMMYFUNCTION("""COMPUTED_VALUE"""),1.0) -> 1 | G23: =IFERROR(__xludf.DUMMYFUNCTION("""COMPUTED_VALUE"""),"PR047") -> PR047 | H23: =IFERROR(__xludf.DUMMYFUNCTION("""COMPUTED_VALUE"""),"VD040") -> VD040 | I23: =IFERROR(__xludf.DUMMYFUNCTION("""COMPUTED_VALUE"""),15.0) -> 15 | J23: =IFERROR(__xludf.DUMMYFUNCTION("""COMPUTED_VALUE"""),4826.84) -> 4826.84 | K23: =IFERROR(__xludf.DUMMYFUNCTION("""COMPUTED_VALUE"""),4826.84) -> 4826.84
A24: =IFERROR(__xludf.DUMMYFUNCTION("""COMPUTED_VALUE"""),1000.0) -> 1000 | B24: =IFERROR(__xludf.DUMMYFUNCTION("""COMPUTED_VALUE"""),183474.0) -> 183474 | C24: =IFERROR(__xludf.DUMMYFUNCTION("""COMPUTED_VALUE"""),2026.0) -> 2026 | D24: =IFERROR(__xludf.DUMMYFUNCTION("""COMPUTED_VALUE"""),46386.0) -> 46386 | E24: =IFERROR(__xludf.DUMMYFUNCTION("""COMPUTED_VALUE"""),"VF") -> VF | F24: =IFERROR(__xludf.DUMMYFUNCTION("""COMPUTED_VALUE"""),1.0) -> 1 | G24: =IFERROR(__xludf.DUMMYFUNCTION("""COMPUTED_VALUE"""),"PR003") -> PR003 | H24: =IFERROR(__xludf.DUMMYFUNCTION("""COMPUTED_VALUE"""),"VD033") -> VD033 | I24: =IFERROR(__xludf.DUMMYFUNCTION("""COMPUTED_VALUE"""),8.0) -> 8 | J24: =IFERROR(__xludf.DUMMYFUNCTION("""COMPUTED_VALUE"""),629.59) -> 629.59 | K24: =IFERROR(__xludf.DUMMYFUNCTION("""COMPUTED_VALUE"""),629.59) -> 629.59
A25: =IFERROR(__xludf.DUMMYFUNCTION("""COMPUTED_VALUE"""),1000.0) -> 1000 | B25: =IFERROR(__xludf.DUMMYFUNCTION("""COMPUTED_VALUE"""),183475.0) -> 183475 | C25: =IFERROR(__xludf.DUMMYFUNCTION("""COMPUTED_VALUE"""),2026.0) -> 2026 | D25: =IFERROR(__xludf.DUMMYFUNCTION("""COMPUTED_VALUE"""),46386.0) -> 46386 | E25: =IFERROR(__xludf.DUMMYFUNCTION("""COMPUTED_VALUE"""),"VF") -> VF | F25: =IFERROR(__xludf.DUMMYFUNCTION("""COMPUTED_VALUE"""),1.0) -> 1 | G25: =IFERROR(__xludf.DUMMYFUNCTION("""COMPUTED_VALUE"""),"PR058") -> PR058 | H25: =IFERROR(__xludf.DUMMYFUNCTION("""COMPUTED_VALUE"""),"VD014") -> VD014 | I25: =IFERROR(__xludf.DUMMYFUNCTION("""COMPUTED_VALUE"""),21.0) -> 21 | J25: =IFERROR(__xludf.DUMMYFUNCTION("""COMPUTED_VALUE"""),4536.0) -> 4536 | K25: =IFERROR(__xludf.DUMMYFUNCTION("""COMPUTED_VALUE"""),4536.0) -> 4536
A26: =IFERROR(__xludf.DUMMYFUNCTION("""COMPUTED_VALUE"""),2000.0) -> 2000 | B26: =IFERROR(__xludf.DUMMYFUNCTION("""COMPUTED_VALUE"""),183476.0) -> 183476 | C26: =IFERROR(__xludf.DUMMYFUNCTION("""COMPUTED_VALUE"""),2026.0) -> 2026 | D26: =IFERROR(__xludf.DUMMYFUNCTION("""COMPUTED_VALUE"""),46386.0) -> 46386 | E26: =IFERROR(__xludf.DUMMYFUNCTION("""COMPUTED_VALUE"""),"VF") -> VF | F26: =IFERROR(__xludf.DUMMYFUNCTION("""COMPUTED_VALUE"""),1.0) -> 1 | G26: =IFERROR(__xludf.DUMMYFUNCTION("""COMPUTED_VALUE"""),"PR049") -> PR049 | H26: =IFERROR(__xludf.DUMMYFUNCTION("""COMPUTED_VALUE"""),"VD029") -> VD029 | I26: =IFERROR(__xludf.DUMMYFUNCTION("""COMPUTED_VALUE"""),12.0) -> 12 | J26: =IFERROR(__xludf.DUMMYFUNCTION("""COMPUTED_VALUE"""),473.76) -> 473.76 | K26: =IFERROR(__xludf.DUMMYFUNCTION("""COMPUTED_VALUE"""),473.76) -> 473.76
A27: =IFERROR(__xludf.DUMMYFUNCTION("""COMPUTED_VALUE"""),1000.0) -> 1000 | B27: =IFERROR(__xludf.DUMMYFUNCTION("""COMPUTED_VALUE"""),183477.0) -> 183477 | C27: =IFERROR(__xludf.DUMMYFUNCTION("""COMPUTED_VALUE"""),2026.0) -> 2026 | D27: =IFERROR(__xludf.DUMMYFUNCTION("""COMPUTED_VALUE"""),46386.0) -> 46386 | E27: =IFERROR(__xludf.DUMMYFUNCTION("""COMPUTED_VALUE"""),"VF") -> VF | F27: =IFERROR(__xludf.DUMMYFUNCTION("""COMPUTED_VALUE"""),1.0) -> 1 | G27: =IFERROR(__xludf.DUMMYFUNCTION("""COMPUTED_VALUE"""),"PR035") -> PR035 | H27: =IFERROR(__xludf.DUMMYFUNCTION("""COMPUTED_VALUE"""),"VD010") -> VD010 | I27: =IFERROR(__xludf.DUMMYFUNCTION("""COMPUTED_VALUE"""),27.0) -> 27 | J27: =IFERROR(__xludf.DUMMYFUNCTION("""COMPUTED_VALUE"""),2763.94) -> 2763.94 | K27: =IFERROR(__xludf.DUMMYFUNCTION("""COMPUTED_VALUE"""),2763.94) -> 2763.94
A28: =IFERROR(__xludf.DUMMYFUNCTION("""COMPUTED_VALUE"""),2000.0) -> 2000 | B28: =IFERROR(__xludf.DUMMYFUNCTION("""COMPUTED_VALUE"""),183478.0) -> 183478 | C28: =IFERROR(__xludf.DUMMYFUNCTION("""COMPUTED_VALUE"""),2026.0) -> 2026 | D28: =IFERROR(__xludf.DUMMYFUNCTION("""COMPUTED_VALUE"""),46386.0) -> 46386 | E28: =IFERROR(__xludf.DUMMYFUNCTION("""COMPUTED_VALUE"""),"VF") -> VF | F28: =IFERROR(__xludf.DUMMYFUNCTION("""COMPUTED_VALUE"""),1.0) -> 1 | G28: =IFERROR(__xludf.DUMMYFUNCTION("""COMPUTED_VALUE"""),"PR003") -> PR003 | H28: =IFERROR(__xludf.DUMMYFUNCTION("""COMPUTED_VALUE"""),"VD024") -> VD024 | I28: =IFERROR(__xludf.DUMMYFUNCTION("""COMPUTED_VALUE"""),18.0) -> 18 | J28: =IFERROR(__xludf.DUMMYFUNCTION("""COMPUTED_VALUE"""),1480.39) -> 1480.39 | K28: =IFERROR(__xludf.DUMMYFUNCTION("""COMPUTED_VALUE"""),1480.39) -> 1480.39
A29: =IFERROR(__xludf.DUMMYFUNCTION("""COMPUTED_VALUE"""),2000.0) -> 2000 | B29: =IFERROR(__xludf.DUMMYFUNCTION("""COMPUTED_VALUE"""),183479.0) -> 183479 | C29: =IFERROR(__xludf.DUMMYFUNCTION("""COMPUTED_VALUE"""),2026.0) -> 2026 | D29: =IFERROR(__xludf.DUMMYFUNCTION("""COMPUTED_VALUE"""),46385.0) -> 46385 | E29: =IFERROR(__xludf.DUMMYFUNCTION("""COMPUTED_VALUE"""),"VF") -> VF | F29: =IFERROR(__xludf.DUMMYFUNCTION("""COMPUTED_VALUE"""),1.0) -> 1 | G29: =IFERROR(__xludf.DUMMYFUNCTION("""COMPUTED_VALUE"""),"PR006") -> PR006 | H29: =IFERROR(__xludf.DUMMYFUNCTION("""COMPUTED_VALUE"""),"VD021") -> VD021 | I29: =IFERROR(__xludf.DUMMYFUNCTION("""COMPUTED_VALUE"""),27.0) -> 27 | J29: =IFERROR(__xludf.DUMMYFUNCTION("""COMPUTED_VALUE"""),1249.67) -> 1249.67 | K29: =IFERROR(__xludf.DUMMYFUNCTION("""COMPUTED_VALUE"""),1249.67) -> 1249.67
A30: =IFERROR(__xludf.DUMMYFUNCTION("""COMPUTED_VALUE"""),1000.0) -> 1000 | B30: =IFERROR(__xludf.DUMMYFUNCTION("""COMPUTED_VALUE"""),183479.0) -> 183479 | C30: =IFERROR(__xludf.DUMMYFUNCTION("""COMPUTED_VALUE"""),2026.0) -> 2026 | D30: =IFERROR(__xludf.DUMMYFUNCTION("""COMPUTED_VALUE"""),46385.0) -> 46385 | E30: =IFERROR(__xludf.DUMMYFUNCTION("""COMPUTED_VALUE"""),"VF") -> VF | F30: =IFERROR(__xludf.DUMMYFUNCTION("""COMPUTED_VALUE"""),2.0) -> 2 | G30: =IFERROR(__xludf.DUMMYFUNCTION("""COMPUTED_VALUE"""),"PR002") -> PR002 | H30: =IFERROR(__xludf.DUMMYFUNCTION("""COMPUTED_VALUE"""),"VD040") -> VD040 | I30: =IFERROR(__xludf.DUMMYFUNCTION("""COMPUTED_VALUE"""),24.0) -> 24 | J30: =IFERROR(__xludf.DUMMYFUNCTION("""COMPUTED_VALUE"""),1996.34) -> 1996.34 | K30: =IFERROR(__xludf.DUMMYFUNCTION("""COMPUTED_VALUE"""),1996.34) -> 1996.34
A31: =IFERROR(__xludf.DUMMYFUNCTION("""COMPUTED_VALUE"""),1000.0) -> 1000 | B31: =IFERROR(__xludf.DUMMYFUNCTION("""COMPUTED_VALUE"""),183479.0) -> 183479 | C31: =IFERROR(__xludf.DUMMYFUNCTION("""COMPUTED_VALUE"""),2026.0) -> 2026 | D31: =IFERROR(__xludf.DUMMYFUNCTION("""COMPUTED_VALUE"""),46384.0) -> 46384 | E31: =IFERROR(__xludf.DUMMYFUNCTION("""COMPUTED_VALUE"""),"VF") -> VF | F31: =IFERROR(__xludf.DUMMYFUNCTION("""COMPUTED_VALUE"""),3.0) -> 3 | G31: =IFERROR(__xludf.DUMMYFUNCTION("""COMPUTED_VALUE"""),"PR038") -> PR038 | H31: =IFERROR(__xludf.DUMMYFUNCTION("""COMPUTED_VALUE"""),"VD016") -> VD016 | I31: =IFERROR(__xludf.DUMMYFUNCTION("""COMPUTED_VALUE"""),12.0) -> 12 | J31: =IFERROR(__xludf.DUMMYFUNCTION("""COMPUTED_VALUE"""),1972.02) -> 1972.02 | K31: =IFERROR(__xludf.DUMMYFUNCTION("""COMPUTED_VALUE"""),1972.02) -> 1972.02
A32: =IFERROR(__xludf.DUMMYFUNCTION("""COMPUTED_VALUE"""),1000.0) -> 1000 | B32: =IFERROR(__xludf.DUMMYFUNCTION("""COMPUTED_VALUE"""),183480.0) -> 183480 | C32: =IFERROR(__xludf.DUMMYFUNCTION("""COMPUTED_VALUE"""),2026.0) -> 2026 | D32: =IFERROR(__xludf.DUMMYFUNCTION("""COMPUTED_VALUE"""),46384.0) -> 46384 | E32: =IFERROR(__xludf.DUMMYFUNCTION("""COMPUTED_VALUE"""),"VF") -> VF | F32: =IFERROR(__xludf.DUMMYFUNCTION("""COMPUTED_VALUE"""),1.0) -> 1 | G32: =IFERROR(__xludf.DUMMYFUNCTION("""COMPUTED_VALUE"""),"PR027") -> PR027 | H32: =IFERROR(__xludf.DUMMYFUNCTION("""COMPUTED_VALUE"""),"VD035") -> VD035 | I32: =IFERROR(__xludf.DUMMYFUNCTION("""COMPUTED_VALUE"""),30.0) -> 30 | J32: =IFERROR(__xludf.DUMMYFUNCTION("""COMPUTED_VALUE"""),3996.0) -> 3996 | K32: =IFERROR(__xludf.DUMMYFUNCTION("""COMPUTED_VALUE"""),3996.0) -> 3996
A33: =IFERROR(__xludf.DUMMYFUNCTION("""COMPUTED_VALUE"""),1000.0) -> 1000 | B33: =IFERROR(__xludf.DUMMYFUNCTION("""COMPUTED_VALUE"""),183480.0) -> 183480 | C33: =IFERROR(__xludf.DUMMYFUNCTION("""COMPUTED_VALUE"""),2026.0) -> 2026 | D33: =IFERROR(__xludf.DUMMYFUNCTION("""COMPUTED_VALUE"""),46384.0) -> 46384 | E33: =IFERROR(__xludf.DUMMYFUNCTION("""COMPUTED_VALUE"""),"VF") -> VF | F33: =IFERROR(__xludf.DUMMYFUNCTION("""COMPUTED_VALUE"""),2.0) -> 2 | G33: =IFERROR(__xludf.DUMMYFUNCTION("""COMPUTED_VALUE"""),"PR059") -> PR059 | H33: =IFERROR(__xludf.DUMMYFUNCTION("""COMPUTED_VALUE"""),"VD049") -> VD049 | I33: =IFERROR(__xludf.DUMMYFUNCTION("""COMPUTED_VALUE"""),12.0) -> 12 | J33: =IFERROR(__xludf.DUMMYFUNCTION("""COMPUTED_VALUE"""),2419.2) -> 2419.2 | K33: =IFERROR(__xludf.DUMMYFUNCTION("""COMPUTED_VALUE"""),2419.2) -> 2419.2
A34: =IFERROR(__xludf.DUMMYFUNCTION("""COMPUTED_VALUE"""),1000.0) -> 1000 | B34: =IFERROR(__xludf.DUMMYFUNCTION("""COMPUTED_VALUE"""),183480.0) -> 183480 | C34: =IFERROR(__xludf.DUMMYFUNCTION("""COMPUTED_VALUE"""),2026.0) -> 2026 | D34: =IFERROR(__xludf.DUMMYFUNCTION("""COMPUTED_VALUE"""),46383.0) -> 46383 | E34: =IFERROR(__xludf.DUMMYFUNCTION("""COMPUTED_VALUE"""),"VF") -> VF | F34: =IFERROR(__xludf.DUMMYFUNCTION("""COMPUTED_VALUE"""),3.0) -> 3 | G34: =IFERROR(__xludf.DUMMYFUNCTION("""COMPUTED_VALUE"""),"PR035") -> PR035 | H34: =IFERROR(__xludf.DUMMYFUNCTION("""COMPUTED_VALUE"""),"VD019") -> VD019 | I34: =IFERROR(__xludf.DUMMYFUNCTION("""COMPUTED_VALUE"""),21.0) -> 21 | J34: =IFERROR(__xludf.DUMMYFUNCTION("""COMPUTED_VALUE"""),2207.31) -> 2207.31 | K34: =IFERROR(__xludf.DUMMYFUNCTION("""COMPUTED_VALUE"""),2207.31) -> 2207.31
A35: =IFERROR(__xludf.DUMMYFUNCTION("""COMPUTED_VALUE"""),1000.0) -> 1000 | B35: =IFERROR(__xludf.DUMMYFUNCTION("""COMPUTED_VALUE"""),183481.0) -> 183481 | C35: =IFERROR(__xludf.DUMMYFUNCTION("""COMPUTED_VALUE"""),2026.0) -> 2026 | D35: =IFERROR(__xludf.DUMMYFUNCTION("""COMPUTED_VALUE"""),46383.0) -> 46383 | E35: =IFERROR(__xludf.DUMMYFUNCTION("""COMPUTED_VALUE"""),"VF") -> VF | F35: =IFERROR(__xludf.DUMMYFUNCTION("""COMPUTED_VALUE"""),1.0) -> 1 | G35: =IFERROR(__xludf.DUMMYFUNCTION("""COMPUTED_VALUE"""),"PR028") -> PR028 | H35: =IFERROR(__xludf.DUMMYFUNCTION("""COMPUTED_VALUE"""),"VD011") -> VD011 | I35: =IFERROR(__xludf.DUMMYFUNCTION("""COMPUTED_VALUE"""),16.0) -> 16 | J35: =IFERROR(__xludf.DUMMYFUNCTION("""COMPUTED_VALUE"""),4718.11) -> 4718.11 | K35: =IFERROR(__xludf.DUMMYFUNCTION("""COMPUTED_VALUE"""),4718.11) -> 4718.11
A36: =IFERROR(__xludf.DUMMYFUNCTION("""COMPUTED_VALUE"""),1000.0) -> 1000 | B36: =IFERROR(__xludf.DUMMYFUNCTION("""COMPUTED_VALUE"""),183482.0) -> 183482 | C36: =IFERROR(__xludf.DUMMYFUNCTION("""COMPUTED_VALUE"""),2026.0) -> 2026 | D36: =IFERROR(__xludf.DUMMYFUNCTION("""COMPUTED_VALUE"""),46382.0) -> 46382 | E36: =IFERROR(__xludf.DUMMYFUNCTION("""COMPUTED_VALUE"""),"VF") -> VF | F36: =IFERROR(__xludf.DUMMYFUNCTION("""COMPUTED_VALUE"""),1.0) -> 1 | G36: =IFERROR(__xludf.DUMMYFUNCTION("""COMPUTED_VALUE"""),"PR018") -> PR018 | H36: =IFERROR(__xludf.DUMMYFUNCTION("""COMPUTED_VALUE"""),"VD016") -> VD016 | I36: =IFERROR(__xludf.DUMMYFUNCTION("""COMPUTED_VALUE"""),10.0) -> 10 | J36: =IFERROR(__xludf.DUMMYFUNCTION("""COMPUTED_VALUE"""),378.35) -> 378.35 | K36: =IFERROR(__xludf.DUMMYFUNCTION("""COMPUTED_VALUE"""),378.35) -> 378.35
A37: =IFERROR(__xludf.DUMMYFUNCTION("""COMPUTED_VALUE"""),2000.0) -> 2000 | B37: =IFERROR(__xludf.DUMMYFUNCTION("""COMPUTED_VALUE"""),183483.0) -> 183483 | C37: =IFERROR(__xludf.DUMMYFUNCTION("""COMPUTED_VALUE"""),2026.0) -> 2026 | D37: =IFERROR(__xludf.DUMMYFUNCTION("""COMPUTED_VALUE"""),46382.0) -> 46382 | E37: =IFERROR(__xludf.DUMMYFUNCTION("""COMPUTED_VALUE"""),"VF") -> VF | F37: =IFERROR(__xludf.DUMMYFUNCTION("""COMPUTED_VALUE"""),1.0) -> 1 | G37: =IFERROR(__xludf.DUMMYFUNCTION("""COMPUTED_VALUE"""),"PR035") -> PR035 | H37: =IFERROR(__xludf.DUMMYFUNCTION("""COMPUTED_VALUE"""),"VD018") -> VD018 | I37: =IFERROR(__xludf.DUMMYFUNCTION("""COMPUTED_VALUE"""),28.0) -> 28 | J37: =IFERROR(__xludf.DUMMYFUNCTION("""COMPUTED_VALUE"""),2149.73) -> 2149.73 | K37: =IFERROR(__xludf.DUMMYFUNCTION("""COMPUTED_VALUE"""),2149.73) -> 2149.73
A38: =IFERROR(__xludf.DUMMYFUNCTION("""COMPUTED_VALUE"""),1000.0) -> 1000 | B38: =IFERROR(__xludf.DUMMYFUNCTION("""COMPUTED_VALUE"""),183483.0) -> 183483 | C38: =IFERROR(__xludf.DUMMYFUNCTION("""COMPUTED_VALUE"""),2026.0) -> 2026 | D38: =IFERROR(__xludf.DUMMYFUNCTION("""COMPUTED_VALUE"""),46381.0) -> 46381 | E38: =IFERROR(__xludf.DUMMYFUNCTION("""COMPUTED_VALUE"""),"VF") -> VF | F38: =IFERROR(__xludf.DUMMYFUNCTION("""COMPUTED_VALUE"""),2.0) -> 2 | G38: =IFERROR(__xludf.DUMMYFUNCTION("""COMPUTED_VALUE"""),"PR057") -> PR057 | H38: =IFERROR(__xludf.DUMMYFUNCTION("""COMPUTED_VALUE"""),"VD034") -> VD034 | I38: =IFERROR(__xludf.DUMMYFUNCTION("""COMPUTED_VALUE"""),9.0) -> 9 | J38: =IFERROR(__xludf.DUMMYFUNCTION("""COMPUTED_VALUE"""),906.19) -> 906.19 | K38: =IFERROR(__xludf.DUMMYFUNCTION("""COMPUTED_VALUE"""),906.19) -> 906.19
A39: =IFERROR(__xludf.DUMMYFUNCTION("""COMPUTED_VALUE"""),1000.0) -> 1000 | B39: =IFERROR(__xludf.DUMMYFUNCTION("""COMPUTED_VALUE"""),183484.0) -> 183484 | C39: =IFERROR(__xludf.DUMMYFUNCTION("""COMPUTED_VALUE"""),2026.0) -> 2026 | D39: =IFERROR(__xludf.DUMMYFUNCTION("""COMPUTED_VALUE"""),46381.0) -> 46381 | E39: =IFERROR(__xludf.DUMMYFUNCTION("""COMPUTED_VALUE"""),"VF") -> VF | F39: =IFERROR(__xludf.DUMMYFUNCTION("""COMPUTED_VALUE"""),1.0) -> 1 | G39: =IFERROR(__xludf.DUMMYFUNCTION("""COMPUTED_VALUE"""),"PR004") -> PR004 | H39: =IFERROR(__xludf.DUMMYFUNCTION("""COMPUTED_VALUE"""),"VD024") -> VD024 | I39: =IFERROR(__xludf.DUMMYFUNCTION("""COMPUTED_VALUE"""),15.0) -> 15 | J39: =IFERROR(__xludf.DUMMYFUNCTION("""COMPUTED_VALUE"""),2610.0) -> 2610 | K39: =IFERROR(__xludf.DUMMYFUNCTION("""COMPUTED_VALUE"""),2610.0) -> 2610
A40: =IFERROR(__xludf.DUMMYFUNCTION("""COMPUTED_VALUE"""),1000.0) -> 1000 | B40: =IFERROR(__xludf.DUMMYFUNCTION("""COMPUTED_VALUE"""),183485.0) -> 183485 | C40: =IFERROR(__xludf.DUMMYFUNCTION("""COMPUTED_VALUE"""),2026.0) -> 2026 | D40: =IFERROR(__xludf.DUMMYFUNCTION("""COMPUTED_VALUE"""),46381.0) -> 46381 | E40: =IFERROR(__xludf.DUMMYFUNCTION("""COMPUTED_VALUE"""),"VF") -> VF | F40: =IFERROR(__xludf.DUMMYFUNCTION("""COMPUTED_VALUE"""),1.0) -> 1 | G40: =IFERROR(__xludf.DUMMYFUNCTION("""COMPUTED_VALUE"""),"PR014") -> PR014 | H40: =IFERROR(__xludf.DUMMYFUNCTION("""COMPUTED_VALUE"""),"VD011") -> VD011 | I40: =IFERROR(__xludf.DUMMYFUNCTION("""COMPUTED_VALUE"""),12.0) -> 12 | J40: =IFERROR(__xludf.DUMMYFUNCTION("""COMPUTED_VALUE"""),560.2) -> 560.2 | K40: =IFERROR(__xludf.DUMMYFUNCTION("""COMPUTED_VALUE"""),560.2) -> 560.2
...

Sheet Productos
A1: =IFERROR(__xludf.DUMMYFUNCTION("IMPORTRANGE(""https://docs.google.com/spreadsheets/d/1wDatiNabBWFvhbng0IgSrI0LbZ9kw3ciTUIdsOHVncU"",""A1:F100"")"),"Código") -> Código | B1: =IFERROR(__xludf.DUMMYFUNCTION("""COMPUTED_VALUE"""),"Producto") -> Producto | C1: =IFERROR(__xludf.DUMMYFUNCTION("""COMPUTED_VALUE"""),"Talla") -> Talla | D1: =IFERROR(__xludf.DUMMYFUNCTION("""COMPUTED_VALUE"""),"Categoría") -> Categoría | E1: =IFERROR(__xludf.DUMMYFUNCTION("""COMPUTED_VALUE"""),"Costo Unitario") -> Costo Unitario | F1: =IFERROR(__xludf.DUMMYFUNCTION("""COMPUTED_VALUE"""),"Precio Unitario") -> Precio Unitario
A2: =IFERROR(__xludf.DUMMYFUNCTION("""COMPUTED_VALUE"""),"PR001") -> PR001 | B2: =IFERROR(__xludf.DUMMYFUNCTION("""COMPUTED_VALUE"""),"Bermuda") -> Bermuda | C2: =IFERROR(__xludf.DUMMYFUNCTION("""COMPUTED_VALUE"""),"S") -> S | D2: =IFERROR(__xludf.DUMMYFUNCTION("""COMPUTED_VALUE"""),"Ropa") -> Ropa | E2: =IFERROR(__xludf.DUMMYFUNCTION("""COMPUTED_VALUE"""),"$35,59") -> $35,59 | F2: =IFERROR(__xludf.DUMMYFUNCTION("""COMPUTED_VALUE"""),"$65,90") -> $65,90
A3: =IFERROR(__xludf.DUMMYFUNCTION("""COMPUTED_VALUE"""),"PR002") -> PR002 | B3: =IFERROR(__xludf.DUMMYFUNCTION("""COMPUTED_VALUE"""),"Bermuda") -> Bermuda | C3: =IFERROR(__xludf.DUMMYFUNCTION("""COMPUTED_VALUE"""),"M") -> M | D3: =IFERROR(__xludf.DUMMYFUNCTION("""COMPUTED_VALUE"""),"Ropa") -> Ropa | E3: =IFERROR(__xludf.DUMMYFUNCTION("""COMPUTED_VALUE"""),"$39,14") -> $39,14 | F3: =IFERROR(__xludf.DUMMYFUNCTION("""COMPUTED_VALUE"""),"$69,90") -> $69,90
A4: =IFERROR(__xludf.DUMMYFUNCTION("""COMPUTED_VALUE"""),"PR003") -> PR003 | B4: =IFERROR(__xludf.DUMMYFUNCTION("""COMPUTED_VALUE"""),"Bermuda") -> Bermuda | C4: =IFERROR(__xludf.DUMMYFUNCTION("""COMPUTED_VALUE"""),"L") -> L | D4: =IFERROR(__xludf.DUMMYFUNCTION("""COMPUTED_VALUE"""),"Ropa") -> Ropa | E4: =IFERROR(__xludf.DUMMYFUNCTION("""COMPUTED_VALUE"""),"$45,38") -> $45,38 | F4: =IFERROR(__xludf.DUMMYFUNCTION("""COMPUTED_VALUE"""),"$70,90") -> $70,90
A5: =IFERROR(__xludf.DUMMYFUNCTION("""COMPUTED_VALUE"""),"PR004") -> PR004 | B5: =IFERROR(__xludf.DUMMYFUNCTION("""COMPUTED_VALUE"""),"Bolso versátil") -> Bolso versátil | C5: =IFERROR(__xludf.DUMMYFUNCTION("""COMPUTED_VALUE"""),"Única") -> Única | D5: =IFERROR(__xludf.DUMMYFUNCTION("""COMPUTED_VALUE"""),"Accesorios") -> Accesorios | E5: =IFERROR(__xludf.DUMMYFUNCTION("""COMPUTED_VALUE"""),"$92,80") -> $92,80 | F5: =IFERROR(__xludf.DUMMYFUNCTION("""COMPUTED_VALUE"""),"$145,00") -> $145,00
A6: =IFERROR(__xludf.DUMMYFUNCTION("""COMPUTED_VALUE"""),"PR005") -> PR005 | B6: =IFERROR(__xludf.DUMMYFUNCTION("""COMPUTED_VALUE"""),"Bolso de cuero") -> Bolso de cuero | C6: =IFERROR(__xludf.DUMMYFUNCTION("""COMPUTED_VALUE"""),"Única") -> Única | D6: =IFERROR(__xludf.DUMMYFUNCTION("""COMPUTED_VALUE"""),"Accesorios") -> Accesorios | E6: =IFERROR(__xludf.DUMMYFUNCTION("""COMPUTED_VALUE"""),"$155,94") -> $155,94 | F6: =IFERROR(__xludf.DUMMYFUNCTION("""COMPUTED_VALUE"""),"$259,90") -> $259,90
A7: =IFERROR(__xludf.DUMMYFUNCTION("""COMPUTED_VALUE"""),"PR006") -> PR006 | B7: =IFERROR(__xludf.DUMMYFUNCTION("""COMPUTED_VALUE"""),"Gorra") -> Gorra | C7: =IFERROR(__xludf.DUMMYFUNCTION("""COMPUTED_VALUE"""),"Única") -> Única | D7: =IFERROR(__xludf.DUMMYFUNCTION("""COMPUTED_VALUE"""),"Accesorios") -> Accesorios | E7: =IFERROR(__xludf.DUMMYFUNCTION("""COMPUTED_VALUE"""),"$27,13") -> $27,13 | F7: =IFERROR(__xludf.DUMMYFUNCTION("""COMPUTED_VALUE"""),"$39,90") -> $39,90
A8: =IFERROR(__xludf.DUMMYFUNCTION("""COMPUTED_VALUE"""),"PR007") -> PR007 | B8: =IFERROR(__xludf.DUMMYFUNCTION("""COMPUTED_VALUE"""),"Pantalón de mezclilla") -> Pantalón de mezclilla | C8: =IFERROR(__xludf.DUMMYFUNCTION("""COMPUTED_VALUE"""),"S") -> S | D8: =IFERROR(__xludf.DUMMYFUNCTION("""COMPUTED_VALUE"""),"Ropa") -> Ropa | E8: =IFERROR(__xludf.DUMMYFUNCTION("""COMPUTED_VALUE"""),"$60,13") -> $60,13 | F8: =IFERROR(__xludf.DUMMYFUNCTION("""COMPUTED_VALUE"""),"$85,90") -> $85,90
A9: =IFERROR(__xludf.DUMMYFUNCTION("""COMPUTED_VALUE"""),"PR008") -> PR008 | B9: =IFERROR(__xludf.DUMMYFUNCTION("""COMPUTED_VALUE"""),"Pantalón de mezclilla") -> Pantalón de mezclilla | C9: =IFERROR(__xludf.DUMMYFUNCTION("""COMPUTED_VALUE"""),"M") -> M | D9: =IFERROR(__xludf.DUMMYFUNCTION("""COMPUTED_VALUE"""),"Ropa") -> Ropa | E9: =IFERROR(__xludf.DUMMYFUNCTION("""COMPUTED_VALUE"""),"$55,74") -> $55,74 | F9: =IFERROR(__xludf.DUMMYFUNCTION("""COMPUTED_VALUE"""),"$89,90") -> $89,90
A10: =IFERROR(__xludf.DUMMYFUNCTION("""COMPUTED_VALUE"""),"PR009") -> PR009 | B10: =IFERROR(__xludf.DUMMYFUNCTION("""COMPUTED_VALUE"""),"Pantalón de mezclilla") -> Pantalón de mezclilla | C10: =IFERROR(__xludf.DUMMYFUNCTION("""COMPUTED_VALUE"""),"L") -> L | D10: =IFERROR(__xludf.DUMMYFUNCTION("""COMPUTED_VALUE"""),"Ropa") -> Ropa | E10: =IFERROR(__xludf.DUMMYFUNCTION("""COMPUTED_VALUE"""),"$64,10") -> $64,10 | F10: =IFERROR(__xludf.DUMMYFUNCTION("""COMPUTED_VALUE"""),"$92,90") -> $92,90
A11: =IFERROR(__xludf.DUMMYFUNCTION("""COMPUTED_VALUE"""),"PR010") -> PR010 | B11: =IFERROR(__xludf.DUMMYFUNCTION("""COMPUTED_VALUE"""),"Pantalón legging") -> Pantalón legging | C11: =IFERROR(__xludf.DUMMYFUNCTION("""COMPUTED_VALUE"""),"S") -> S | D11: =IFERROR(__xludf.DUMMYFUNCTION("""COMPUTED_VALUE"""),"Ropa") -> Ropa | E11: =IFERROR(__xludf.DUMMYFUNCTION("""COMPUTED_VALUE"""),"$27,39") -> $27,39 | F11: =IFERROR(__xludf.DUMMYFUNCTION("""COMPUTED_VALUE"""),"$44,90") -> $44,90
A12: =IFERROR(__xludf.DUMMYFUNCTION("""COMPUTED_VALUE"""),"PR011") -> PR011 | B12: =IFERROR(__xludf.DUMMYFUNCTION("""COMPUTED_VALUE"""),"Pantalón legging") -> Pantalón legging | C12: =IFERROR(__xludf.DUMMYFUNCTION("""COMPUTED_VALUE"""),"M") -> M | D12: =IFERROR(__xludf.DUMMYFUNCTION("""COMPUTED_VALUE"""),"Ropa") -> Ropa | E12: =IFERROR(__xludf.DUMMYFUNCTION("""COMPUTED_VALUE"""),"$23,92") -> $23,92 | F12: =IFERROR(__xludf.DUMMYFUNCTION("""COMPUTED_VALUE"""),"$46,90") -> $46,90
A13: =IFERROR(__xludf.DUMMYFUNCTION("""COMPUTED_VALUE"""),"PR012") -> PR012 | B13: =IFERROR(__xludf.DUMMYFUNCTION("""COMPUTED_VALUE"""),"Pantalón legging") -> Pantalón legging | C13: =IFERROR(__xludf.DUMMYFUNCTION("""COMPUTED_VALUE"""),"L") -> L | D13: =IFERROR(__xludf.DUMMYFUNCTION("""COMPUTED_VALUE"""),"Ropa") -> Ropa | E13: =IFERROR(__xludf.DUMMYFUNCTION("""COMPUTED_VALUE"""),"$28,85") -> $28,85 | F13: =IFERROR(__xludf.DUMMYFUNCTION("""COMPUTED_VALUE"""),"$48,90") -> $48,90
A14: =IFERROR(__xludf.DUMMYFUNCTION("""COMPUTED_VALUE"""),"PR013") -> PR013 | B14: =IFERROR(__xludf.DUMMYFUNCTION("""COMPUTED_VALUE"""),"Playera estampada") -> Playera estampada | C14: =IFERROR(__xludf.DUMMYFUNCTION("""COMPUTED_VALUE"""),"S") -> S | D14: =IFERROR(__xludf.DUMMYFUNCTION("""COMPUTED_VALUE"""),"Ropa") -> Ropa | E14: =IFERROR(__xludf.DUMMYFUNCTION("""COMPUTED_VALUE"""),"$27,53") -> $27,53 | F14: =IFERROR(__xludf.DUMMYFUNCTION("""COMPUTED_VALUE"""),"$39,90") -> $39,90
A15: =IFERROR(__xludf.DUMMYFUNCTION("""COMPUTED_VALUE"""),"PR014") -> PR014 | B15: =IFERROR(__xludf.DUMMYFUNCTION("""COMPUTED_VALUE"""),"Playera estampada") -> Playera estampada | C15: =IFERROR(__xludf.DUMMYFUNCTION("""COMPUTED_VALUE"""),"M") -> M | D15: =IFERROR(__xludf.DUMMYFUNCTION("""COMPUTED_VALUE"""),"Ropa") -> Ropa | E15: =IFERROR(__xludf.DUMMYFUNCTION("""COMPUTED_VALUE"""),"$20,75") -> $20,75 | F15: =IFERROR(__xludf.DUMMYFUNCTION("""COMPUTED_VALUE"""),"$39,90") -> $39,90
A16: =IFERROR(__xludf.DUMMYFUNCTION("""COMPUTED_VALUE"""),"PR015") -> PR015 | B16: =IFERROR(__xludf.DUMMYFUNCTION("""COMPUTED_VALUE"""),"Playera estampada") -> Playera estampada | C16: =IFERROR(__xludf.DUMMYFUNCTION("""COMPUTED_VALUE"""),"L") -> L | D16: =IFERROR(__xludf.DUMMYFUNCTION("""COMPUTED_VALUE"""),"Ropa") -> Ropa | E16: =IFERROR(__xludf.DUMMYFUNCTION("""COMPUTED_VALUE"""),"$25,50") -> $25,50 | F16: =IFERROR(__xludf.DUMMYFUNCTION("""COMPUTED_VALUE"""),"$42,50") -> $42,50
A17: =IFERROR(__xludf.DUMMYFUNCTION("""COMPUTED_VALUE"""),"PR016") -> PR016 | B17: =IFERROR(__xludf.DUMMYFUNCTION("""COMPUTED_VALUE"""),"Playera lisa") -> Playera lisa | C17: =IFERROR(__xludf.DUMMYFUNCTION("""COMPUTED_VALUE"""),"S") -> S | D17: =IFERROR(__xludf.DUMMYFUNCTION("""COMPUTED_VALUE"""),"Ropa") -> Ropa | E17: =IFERROR(__xludf.DUMMYFUNCTION("""COMPUTED_VALUE"""),"$13,21") -> $13,21 | F17: =IFERROR(__xludf.DUMMYFUNCTION("""COMPUTED_VALUE"""),"$25,90") -> $25,90
A18: =IFERROR(__xludf.DUMMYFUNCTION("""COMPUTED_VALUE"""),"PR017") -> PR017 | B18: =IFERROR(__xludf.DUMMYFUNCTION("""COMPUTED_VALUE"""),"Playera lisa") -> Playera lisa | C18: =IFERROR(__xludf.DUMMYFUNCTION("""COMPUTED_VALUE"""),"M") -> M | D18: =IFERROR(__xludf.DUMMYFUNCTION("""COMPUTED_VALUE"""),"Ropa") -> Ropa | E18: =IFERROR(__xludf.DUMMYFUNCTION("""COMPUTED_VALUE"""),"$17,34") -> $17,34 | F18: =IFERROR(__xludf.DUMMYFUNCTION("""COMPUTED_VALUE"""),"$29,90") -> $29,90
A19: =IFERROR(__xludf.DUMMYFUNCTION("""COMPUTED_VALUE"""),"PR018") -> PR018 | B19: =IFERROR(__xludf.DUMMYFUNCTION("""COMPUTED_VALUE"""),"Playera lisa") -> Playera lisa | C19: =IFERROR(__xludf.DUMMYFUNCTION("""COMPUTED_VALUE"""),"L") -> L | D19: =IFERROR(__xludf.DUMMYFUNCTION("""COMPUTED_VALUE"""),"Ropa") -> Ropa | E19: =IFERROR(__xludf.DUMMYFUNCTION("""COMPUTED_VALUE"""),"$17,77") -> $17,77 | F19: =IFERROR(__xludf.DUMMYFUNCTION("""COMPUTED_VALUE"""),"$32,90") -> $32,90
A20: =IFERROR(__xludf.DUMMYFUNCTION("""COMPUTED_VALUE"""),"PR019") -> PR019 | B20: =IFERROR(__xludf.DUMMYFUNCTION("""COMPUTED_VALUE"""),"Cinturón") -> Cinturón | C20: =IFERROR(__xludf.DUMMYFUNCTION("""COMPUTED_VALUE"""),"Única") -> Única | D20: =IFERROR(__xludf.DUMMYFUNCTION("""COMPUTED_VALUE"""),"Accesorios") -> Accesorios | E20: =IFERROR(__xludf.DUMMYFUNCTION("""COMPUTED_VALUE"""),"$34,43") -> $34,43 | F20: =IFERROR(__xludf.DUMMYFUNCTION("""COMPUTED_VALUE"""),"$49,90") -> $49,90
A21: =IFERROR(__xludf.DUMMYFUNCTION("""COMPUTED_VALUE"""),"PR020") -> PR020 | B21: =IFERROR(__xludf.DUMMYFUNCTION("""COMPUTED_VALUE"""),"Chaqueta de cuero") -> Chaqueta de cuero | C21: =IFERROR(__xludf.DUMMYFUNCTION("""COMPUTED_VALUE"""),"S") -> S | D21: =IFERROR(__xludf.DUMMYFUNCTION("""COMPUTED_VALUE"""),"Ropa") -> Ropa | E21: =IFERROR(__xludf.DUMMYFUNCTION("""COMPUTED_VALUE"""),"$164,95") -> $164,95 | F21: =IFERROR(__xludf.DUMMYFUNCTION("""COMPUTED_VALUE"""),"$299,90") -> $299,90
A22: =IFERROR(__xludf.DUMMYFUNCTION("""COMPUTED_VALUE"""),"PR021") -> PR021 | B22: =IFERROR(__xludf.DUMMYFUNCTION("""COMPUTED_VALUE"""),"Chaqueta de cuero") -> Chaqueta de cuero | C22: =IFERROR(__xludf.DUMMYFUNCTION("""COMPUTED_VALUE"""),"M") -> M | D22: =IFERROR(__xludf.DUMMYFUNCTION("""COMPUTED_VALUE"""),"Ropa") -> Ropa | E22: =IFERROR(__xludf.DUMMYFUNCTION("""COMPUTED_VALUE"""),"$178,71") -> $178,71 | F22: =IFERROR(__xludf.DUMMYFUNCTION("""COMPUTED_VALUE"""),"$302,90") -> $302,90
A23: =IFERROR(__xludf.DUMMYFUNCTION("""COMPUTED_VALUE"""),"PR022") -> PR022 | B23: =IFERROR(__xludf.DUMMYFUNCTION("""COMPUTED_VALUE"""),"Chaqueta de cuero") -> Chaqueta de cuero | C23: =IFERROR(__xludf.DUMMYFUNCTION("""COMPUTED_VALUE"""),"L") -> L | D23: =IFERROR(__xludf.DUMMYFUNCTION("""COMPUTED_VALUE"""),"Ropa") -> Ropa | E23: =IFERROR(__xludf.DUMMYFUNCTION("""COMPUTED_VALUE"""),"$186,00") -> $186,00 | F23: =IFERROR(__xludf.DUMMYFUNCTION("""COMPUTED_VALUE"""),"$300,00") -> $300,00
A24: =IFERROR(__xludf.DUMMYFUNCTION("""COMPUTED_VALUE"""),"PR023") -> PR023 | B24: =IFERROR(__xludf.DUMMYFUNCTION("""COMPUTED_VALUE"""),"Chaqueta de mezclilla") -> Chaqueta de mezclilla | C24: =IFERROR(__xludf.DUMMYFUNCTION("""COMPUTED_VALUE"""),"S") -> S | D24: =IFERROR(__xludf.DUMMYFUNCTION("""COMPUTED_VALUE"""),"Ropa") -> Ropa | E24: =IFERROR(__xludf.DUMMYFUNCTION("""COMPUTED_VALUE"""),"$167,43") -> $167,43 | F24: =IFERROR(__xludf.DUMMYFUNCTION("""COMPUTED_VALUE"""),"$249,90") -> $249,90
A25: =IFERROR(__xludf.DUMMYFUNCTION("""COMPUTED_VALUE"""),"PR024") -> PR024 | B25: =IFERROR(__xludf.DUMMYFUNCTION("""COMPUTED_VALUE"""),"Chaqueta de mezclilla") -> Chaqueta de mezclilla | C25: =IFERROR(__xludf.DUMMYFUNCTION("""COMPUTED_VALUE"""),"M") -> M | D25: =IFERROR(__xludf.DUMMYFUNCTION("""COMPUTED_VALUE"""),"Ropa") -> Ropa | E25: =IFERROR(__xludf.DUMMYFUNCTION("""COMPUTED_VALUE"""),"$168,94") -> $168,94 | F25: =IFERROR(__xludf.DUMMYFUNCTION("""COMPUTED_VALUE"""),"$259,90") -> $259,90
A26: =IFERROR(__xludf.DUMMYFUNCTION("""COMPUTED_VALUE"""),"PR025") -> PR025 | B26: =IFERROR(__xludf.DUMMYFUNCTION("""COMPUTED_VALUE"""),"Chaqueta de mezclilla") -> Chaqueta de mezclilla | C26: =IFERROR(__xludf.DUMMYFUNCTION("""COMPUTED_VALUE"""),"L") -> L | D26: =IFERROR(__xludf.DUMMYFUNCTION("""COMPUTED_VALUE"""),"Ropa") -> Ropa | E26: =IFERROR(__xludf.DUMMYFUNCTION("""COMPUTED_VALUE"""),"$155,95") -> $155,95 | F26: =IFERROR(__xludf.DUMMYFUNCTION("""COMPUTED_VALUE"""),"$299,90") -> $299,90
A27: =IFERROR(__xludf.DUMMYFUNCTION("""COMPUTED_VALUE"""),"PR026") -> PR026 | B27: =IFERROR(__xludf.DUMMYFUNCTION("""COMPUTED_VALUE"""),"Gafas cuadradas") -> Gafas cuadradas | C27: =IFERROR(__xludf.DUMMYFUNCTION("""COMPUTED_VALUE"""),"Única") -> Única | D27: =IFERROR(__xludf.DUMMYFUNCTION("""COMPUTED_VALUE"""),"Accesorios") -> Accesorios | E27: =IFERROR(__xludf.DUMMYFUNCTION("""COMPUTED_VALUE"""),"$199,44") -> $199,44 | F27: =IFERROR(__xludf.DUMMYFUNCTION("""COMPUTED_VALUE"""),"$349,90") -> $349,90
A28: =IFERROR(__xludf.DUMMYFUNCTION("""COMPUTED_VALUE"""),"PR027") -> PR027 | B28: =IFERROR(__xludf.DUMMYFUNCTION("""COMPUTED_VALUE"""),"Gafas redondas") -> Gafas redondas | C28: =IFERROR(__xludf.DUMMYFUNCTION("""COMPUTED_VALUE"""),"Única") -> Única | D28: =IFERROR(__xludf.DUMMYFUNCTION("""COMPUTED_VALUE"""),"Accesorios") -> Accesorios | E28: =IFERROR(__xludf.DUMMYFUNCTION("""COMPUTED_VALUE"""),"$66,00") -> $66,00 | F28: =IFERROR(__xludf.DUMMYFUNCTION("""COMPUTED_VALUE"""),"$120,00") -> $120,00
A29: =IFERROR(__xludf.DUMMYFUNCTION("""COMPUTED_VALUE"""),"PR028") -> PR028 | B29: =IFERROR(__xludf.DUMMYFUNCTION("""COMPUTED_VALUE"""),"Tenis Atitas") -> Tenis Atitas | C29: =IFERROR(__xludf.DUMMYFUNCTION("""COMPUTED_VALUE"""),36.0) -> 36 | D29: =IFERROR(__xludf.DUMMYFUNCTION("""COMPUTED_VALUE"""),"Calzado") -> Calzado | E29: =IFERROR(__xludf.DUMMYFUNCTION("""COMPUTED_VALUE"""),"$154,94") -> $154,94 | F29: =IFERROR(__xludf.DUMMYFUNCTION("""COMPUTED_VALUE"""),"$249,90") -> $249,90
A30: =IFERROR(__xludf.DUMMYFUNCTION("""COMPUTED_VALUE"""),"PR029") -> PR029 | B30: =IFERROR(__xludf.DUMMYFUNCTION("""COMPUTED_VALUE"""),"Tenis Atitas") -> Tenis Atitas | C30: =IFERROR(__xludf.DUMMYFUNCTION("""COMPUTED_VALUE"""),37.0) -> 37 | D30: =IFERROR(__xludf.DUMMYFUNCTION("""COMPUTED_VALUE"""),"Calzado") -> Calzado | E30: =IFERROR(__xludf.DUMMYFUNCTION("""COMPUTED_VALUE"""),"$145,35") -> $145,35 | F30: =IFERROR(__xludf.DUMMYFUNCTION("""COMPUTED_VALUE"""),"$255,00") -> $255,00
A31: =IFERROR(__xludf.DUMMYFUNCTION("""COMPUTED_VALUE"""),"PR030") -> PR030 | B31: =IFERROR(__xludf.DUMMYFUNCTION("""COMPUTED_VALUE"""),"Tenis Atitas") -> Tenis Atitas | C31: =IFERROR(__xludf.DUMMYFUNCTION("""COMPUTED_VALUE"""),38.0) -> 38 | D31: =IFERROR(__xludf.DUMMYFUNCTION("""COMPUTED_VALUE"""),"Calzado") -> Calzado | E31: =IFERROR(__xludf.DUMMYFUNCTION("""COMPUTED_VALUE"""),"$153,34") -> $153,34 | F31: =IFERROR(__xludf.DUMMYFUNCTION("""COMPUTED_VALUE"""),"$259,90") -> $259,90
A32: =IFERROR(__xludf.DUMMYFUNCTION("""COMPUTED_VALUE"""),"PR031") -> PR031 | B32: =IFERROR(__xludf.DUMMYFUNCTION("""COMPUTED_VALUE"""),"Tenis Chunky") -> Tenis Chunky | C32: =IFERROR(__xludf.DUMMYFUNCTION("""COMPUTED_VALUE"""),36.0) -> 36 | D32: =IFERROR(__xludf.DUMMYFUNCTION("""COMPUTED_VALUE"""),"Calzado") -> Calzado | E32: =IFERROR(__xludf.DUMMYFUNCTION("""COMPUTED_VALUE"""),"$156,80") -> $156,80 | F32: =IFERROR(__xludf.DUMMYFUNCTION("""COMPUTED_VALUE"""),"$245,00") -> $245,00
A33: =IFERROR(__xludf.DUMMYFUNCTION("""COMPUTED_VALUE"""),"PR032") -> PR032 | B33: =IFERROR(__xludf.DUMMYFUNCTION("""COMPUTED_VALUE"""),"Tenis Chunky") -> Tenis Chunky | C33: =IFERROR(__xludf.DUMMYFUNCTION("""COMPUTED_VALUE"""),37.0) -> 37 | D33: =IFERROR(__xludf.DUMMYFUNCTION("""COMPUTED_VALUE"""),"Calzado") -> Calzado | E33: =IFERROR(__xludf.DUMMYFUNCTION("""COMPUTED_VALUE"""),"$152,50") -> $152,50 | F33: =IFERROR(__xludf.DUMMYFUNCTION("""COMPUTED_VALUE"""),"$250,00") -> $250,00
A34: =IFERROR(__xludf.DUMMYFUNCTION("""COMPUTED_VALUE"""),"PR033") -> PR033 | B34: =IFERROR(__xludf.DUMMYFUNCTION("""COMPUTED_VALUE"""),"Tenis Chunky") -> Tenis Chunky | C34: =IFERROR(__xludf.DUMMYFUNCTION("""COMPUTED_VALUE"""),38.0) -> 38 | D34: =IFERROR(__xludf.DUMMYFUNCTION("""COMPUTED_VALUE"""),"Calzado") -> Calzado | E34: =IFERROR(__xludf.DUMMYFUNCTION("""COMPUTED_VALUE"""),"$153,34") -> $153,34 | F34: =IFERROR(__xludf.DUMMYFUNCTION("""COMPUTED_VALUE"""),"$259,90") -> $259,90
A35: =IFERROR(__xludf.DUMMYFUNCTION("""COMPUTED_VALUE"""),"PR034") -> PR034 | B35: =IFERROR(__xludf.DUMMYFUNCTION("""COMPUTED_VALUE"""),"Vestido corto") -> Vestido corto | C35: =IFERROR(__xludf.DUMMYFUNCTION("""COMPUTED_VALUE"""),"S") -> S | D35: =IFERROR(__xludf.DUMMYFUNCTION("""COMPUTED_VALUE"""),"Ropa") -> Ropa | E35: =IFERROR(__xludf.DUMMYFUNCTION("""COMPUTED_VALUE"""),"$59,33") -> $59,33 | F35: =IFERROR(__xludf.DUMMYFUNCTION("""COMPUTED_VALUE"""),"$89,90") -> $89,90
A36: =IFERROR(__xludf.DUMMYFUNCTION("""COMPUTED_VALUE"""),"PR035") -> PR035 | B36: =IFERROR(__xludf.DUMMYFUNCTION("""COMPUTED_VALUE"""),"Vestido corto") -> Vestido corto | C36: =IFERROR(__xludf.DUMMYFUNCTION("""COMPUTED_VALUE"""),"M") -> M | D36: =IFERROR(__xludf.DUMMYFUNCTION("""COMPUTED_VALUE"""),"Ropa") -> Ropa | E36: =IFERROR(__xludf.DUMMYFUNCTION("""COMPUTED_VALUE"""),"$46,61") -> $46,61 | F36: =IFERROR(__xludf.DUMMYFUNCTION("""COMPUTED_VALUE"""),"$91,40") -> $91,40
A37: =IFERROR(__xludf.DUMMYFUNCTION("""COMPUTED_VALUE"""),"PR036") -> PR036 | B37: =IFERROR(__xludf.DUMMYFUNCTION("""COMPUTED_VALUE"""),"Vestido corto") -> Vestido corto | C37: =IFERROR(__xludf.DUMMYFUNCTION("""COMPUTED_VALUE"""),"L") -> L | D37: =IFERROR(__xludf.DUMMYFUNCTION("""COMPUTED_VALUE"""),"Ropa") -> Ropa | E37: =IFERROR(__xludf.DUMMYFUNCTION("""COMPUTED_VALUE"""),"$52,36") -> $52,36 | F37: =IFERROR(__xludf.DUMMYFUNCTION("""COMPUTED_VALUE"""),"$93,50") -> $93,50
A38: =IFERROR(__xludf.DUMMYFUNCTION("""COMPUTED_VALUE"""),"PR037") -> PR037 | B38: =IFERROR(__xludf.DUMMYFUNCTION("""COMPUTED_VALUE"""),"Vestido largo") -> Vestido largo | C38: =IFERROR(__xludf.DUMMYFUNCTION("""COMPUTED_VALUE"""),"S") -> S | D38: =IFERROR(__xludf.DUMMYFUNCTION("""COMPUTED_VALUE"""),"Ropa") -> Ropa | E38: =IFERROR(__xludf.DUMMYFUNCTION("""COMPUTED_VALUE"""),"$70,00") -> $70,00 | F38: =IFERROR(__xludf.DUMMYFUNCTION("""COMPUTED_VALUE"""),"$140,00") -> $140,00
A39: =IFERROR(__xludf.DUMMYFUNCTION("""COMPUTED_VALUE"""),"PR038") -> PR038 | B39: =IFERROR(__xludf.DUMMYFUNCTION("""COMPUTED_VALUE"""),"Vestido largo") -> Vestido largo | C39: =IFERROR(__xludf.DUMMYFUNCTION("""COMPUTED_VALUE"""),"M") -> M | D39: =IFERROR(__xludf.DUMMYFUNCTION("""COMPUTED_VALUE"""),"Ropa") -> Ropa | E39: =IFERROR(__xludf.DUMMYFUNCTION("""COMPUTED_VALUE"""),"$98,60") -> $98,60 | F39: =IFERROR(__xludf.DUMMYFUNCTION("""COMPUTED_VALUE"""),"$142,90") -> $142,90
A40: =IFERROR(__xludf.DUMMYFUNCTION("""COMPUTED_VALUE"""),"PR039") -> PR039 | B40: =IFERROR(__xludf.DUMMYFUNCTION("""COMPUTED_VALUE"""),"Vestido largo") -> Vestido largo | C40: =IFERROR(__xludf.DUMMYFUNCTION("""COMPUTED_VALUE"""),"L") -> L | D40: =IFERROR(__xludf.DUMMYFUNCTION("""COMPUTED_VALUE"""),"Ropa") -> Ropa | E40: =IFERROR(__xludf.DUMMYFUNCTION("""COMPUTED_VALUE"""),"$90,52") -> $90,52 | F40: =IFERROR(__xludf.DUMMYFUNCTION("""COMPUTED_VALUE"""),"$146,00") -> $146,00
...

Sheet Vendedores
A1: =IFERROR(__xludf.DUMMYFUNCTION("IMPORTRANGE(""https://docs.google.com/spreadsheets/d/1vaJzUnOrtKtLng2PhfFKCWSC4LAsqa8tmcEg1rv0FIM/"",""A1:D50"")"),"Código") -> Código | B1: =IFERROR(__xludf.DUMMYFUNCTION("""COMPUTED_VALUE"""),"Vendedor") -> Vendedor | C1: =IFERROR(__xludf.DUMMYFUNCTION("""COMPUTED_VALUE"""),"Ciudad") -> Ciudad | D1: =IFERROR(__xludf.DUMMYFUNCTION("""COMPUTED_VALUE"""),"Región") -> Región
A2: =IFERROR(__xludf.DUMMYFUNCTION("""COMPUTED_VALUE"""),"VD010") -> VD010 | B2: =IFERROR(__xludf.DUMMYFUNCTION("""COMPUTED_VALUE"""),"María Silva") -> María Silva | C2: =IFERROR(__xludf.DUMMYFUNCTION("""COMPUTED_VALUE"""),"San Juan de la Sierra") -> San Juan de la Sierra | D2: =IFERROR(__xludf.DUMMYFUNCTION("""COMPUTED_VALUE"""),"Región Central") -> Región Central
A3: =IFERROR(__xludf.DUMMYFUNCTION("""COMPUTED_VALUE"""),"VD011") -> VD011 | B3: =IFERROR(__xludf.DUMMYFUNCTION("""COMPUTED_VALUE"""),"Juan Santos") -> Juan Santos | C3: =IFERROR(__xludf.DUMMYFUNCTION("""COMPUTED_VALUE"""),"Vista Hermosa") -> Vista Hermosa | D3: =IFERROR(__xludf.DUMMYFUNCTION("""COMPUTED_VALUE"""),"Región Central") -> Región Central
A4: =IFERROR(__xludf.DUMMYFUNCTION("""COMPUTED_VALUE"""),"VD012") -> VD012 | B4: =IFERROR(__xludf.DUMMYFUNCTION("""COMPUTED_VALUE"""),"Ana Olmedo") -> Ana Olmedo | C4: =IFERROR(__xludf.DUMMYFUNCTION("""COMPUTED_VALUE"""),"Río Claro") -> Río Claro | D4: =IFERROR(__xludf.DUMMYFUNCTION("""COMPUTED_VALUE"""),"Región Central") -> Región Central
A5: =IFERROR(__xludf.DUMMYFUNCTION("""COMPUTED_VALUE"""),"VD013") -> VD013 | B5: =IFERROR(__xludf.DUMMYFUNCTION("""COMPUTED_VALUE"""),"Pedro Almonte") -> Pedro Almonte | C5: =IFERROR(__xludf.DUMMYFUNCTION("""COMPUTED_VALUE"""),"Santa Rosa del Valle") -> Santa Rosa del Valle | D5: =IFERROR(__xludf.DUMMYFUNCTION("""COMPUTED_VALUE"""),"Región Norte") -> Región Norte
A6: =IFERROR(__xludf.DUMMYFUNCTION("""COMPUTED_VALUE"""),"VD014") -> VD014 | B6: =IFERROR(__xludf.DUMMYFUNCTION("""COMPUTED_VALUE"""),"Carla Flores") -> Carla Flores | C6: =IFERROR(__xludf.DUMMYFUNCTION("""COMPUTED_VALUE"""),"Valle Escondido") -> Valle Escondido | D6: =IFERROR(__xludf.DUMMYFUNCTION("""COMPUTED_VALUE"""),"Región Andina") -> Región Andina
A7: =IFERROR(__xludf.DUMMYFUNCTION("""COMPUTED_VALUE"""),"VD015") -> VD015 | B7: =IFERROR(__xludf.DUMMYFUNCTION("""COMPUTED_VALUE"""),"Lucas Castillo") -> Lucas Castillo | C7: =IFERROR(__xludf.DUMMYFUNCTION("""COMPUTED_VALUE"""),"San Miguel de los Pinos") -> San Miguel de los Pinos | D7: =IFERROR(__xludf.DUMMYFUNCTION("""COMPUTED_VALUE"""),"Región Sur") -> Región Sur
A8: =IFERROR(__xludf.DUMMYFUNCTION("""COMPUTED_VALUE"""),"VD016") -> VD016 | B8: =IFERROR(__xludf.DUMMYFUNCTION("""COMPUTED_VALUE"""),"Beatriz Linares") -> Beatriz Linares | C8: =IFERROR(__xludf.DUMMYFUNCTION("""COMPUTED_VALUE"""),"Puerto Esperanza") -> Puerto Esperanza | D8: =IFERROR(__xludf.DUMMYFUNCTION("""COMPUTED_VALUE"""),"Región Sur") -> Región Sur
A9: =IFERROR(__xludf.DUMMYFUNCTION("""COMPUTED_VALUE"""),"VD017") -> VD017 | B9: =IFERROR(__xludf.DUMMYFUNCTION("""COMPUTED_VALUE"""),"Bruno Peralta") -> Bruno Peralta | C9: =IFERROR(__xludf.DUMMYFUNCTION("""COMPUTED_VALUE"""),"Costa Azul") -> Costa Azul | D9: =IFERROR(__xludf.DUMMYFUNCTION("""COMPUTED_VALUE"""),"Región Norte") -> Región Norte
A10: =IFERROR(__xludf.DUMMYFUNCTION("""COMPUTED_VALUE"""),"VD018") -> VD018 | B10: =IFERROR(__xludf.DUMMYFUNCTION("""COMPUTED_VALUE"""),"Leticia Rodríguez") -> Leticia Rodríguez | C10: =IFERROR(__xludf.DUMMYFUNCTION("""COMPUTED_VALUE"""),"Playa Blanca") -> Playa Blanca | D10: =IFERROR(__xludf.DUMMYFUNCTION("""COMPUTED_VALUE"""),"Región Norte") -> Región Norte
A11: =IFERROR(__xludf.DUMMYFUNCTION("""COMPUTED_VALUE"""),"VD019") -> VD019 | B11: =IFERROR(__xludf.DUMMYFUNCTION("""COMPUTED_VALUE"""),"Rafael Sosa") -> Rafael Sosa | C11: =IFERROR(__xludf.DUMMYFUNCTION("""COMPUTED_VALUE"""),"Selva Verde") -> Selva Verde | D11: =IFERROR(__xludf.DUMMYFUNCTION("""COMPUTED_VALUE"""),"Región Amazónica") -> Región Amazónica
A12: =IFERROR(__xludf.DUMMYFUNCTION("""COMPUTED_VALUE"""),"VD020") -> VD020 | B12: =IFERROR(__xludf.DUMMYFUNCTION("""COMPUTED_VALUE"""),"Gustavo Morales") -> Gustavo Morales | C12: =IFERROR(__xludf.DUMMYFUNCTION("""COMPUTED_VALUE"""),"Villa del Sol") -> Villa del Sol | D12: =IFERROR(__xludf.DUMMYFUNCTION("""COMPUTED_VALUE"""),"Región Central 2") -> Región Central 2
A13: =IFERROR(__xludf.DUMMYFUNCTION("""COMPUTED_VALUE"""),"VD021") -> VD021 | B13: =IFERROR(__xludf.DUMMYFUNCTION("""COMPUTED_VALUE"""),"Fernanda Méndez") -> Fernanda Méndez | C13: =IFERROR(__xludf.DUMMYFUNCTION("""COMPUTED_VALUE"""),"San Juan de la Sierra") -> San Juan de la Sierra | D13: =IFERROR(__xludf.DUMMYFUNCTION("""COMPUTED_VALUE"""),"Región Central") -> Región Central
A14: =IFERROR(__xludf.DUMMYFUNCTION("""COMPUTED_VALUE"""),"VD022") -> VD022 | B14: =IFERROR(__xludf.DUMMYFUNCTION("""COMPUTED_VALUE"""),"Santiago Linares") -> Santiago Linares | C14: =IFERROR(__xludf.DUMMYFUNCTION("""COMPUTED_VALUE"""),"Vista Hermosa") -> Vista Hermosa | D14: =IFERROR(__xludf.DUMMYFUNCTION("""COMPUTED_VALUE"""),"Región Central") -> Región Central
A15: =IFERROR(__xludf.DUMMYFUNCTION("""COMPUTED_VALUE"""),"VD023") -> VD023 | B15: =IFERROR(__xludf.DUMMYFUNCTION("""COMPUTED_VALUE"""),"Juliana Castro") -> Juliana Castro | C15: =IFERROR(__xludf.DUMMYFUNCTION("""COMPUTED_VALUE"""),"San Miguel de los Pinos") -> San Miguel de los Pinos | D15: =IFERROR(__xludf.DUMMYFUNCTION("""COMPUTED_VALUE"""),"Región Sur") -> Región Sur
A16: =IFERROR(__xludf.DUMMYFUNCTION("""COMPUTED_VALUE"""),"VD024") -> VD024 | B16: =IFERROR(__xludf.DUMMYFUNCTION("""COMPUTED_VALUE"""),"Marcos Rivera") -> Marcos Rivera | C16: =IFERROR(__xludf.DUMMYFUNCTION("""COMPUTED_VALUE"""),"Santa Rosa del Valle") -> Santa Rosa del Valle | D16: =IFERROR(__xludf.DUMMYFUNCTION("""COMPUTED_VALUE"""),"Región Norte") -> Región Norte
A17: =IFERROR(__xludf.DUMMYFUNCTION("""COMPUTED_VALUE"""),"VD025") -> VD025 | B17: =IFERROR(__xludf.DUMMYFUNCTION("""COMPUTED_VALUE"""),"Alina Santana") -> Alina Santana | C17: =IFERROR(__xludf.DUMMYFUNCTION("""COMPUTED_VALUE"""),"Playa Blanca") -> Playa Blanca | D17: =IFERROR(__xludf.DUMMYFUNCTION("""COMPUTED_VALUE"""),"Región Norte") -> Región Norte
A18: =IFERROR(__xludf.DUMMYFUNCTION("""COMPUTED_VALUE"""),"VD026") -> VD026 | B18: =IFERROR(__xludf.DUMMYFUNCTION("""COMPUTED_VALUE"""),"Daniel Fernández") -> Daniel Fernández | C18: =IFERROR(__xludf.DUMMYFUNCTION("""COMPUTED_VALUE"""),"Puerto Esperanza") -> Puerto Esperanza | D18: =IFERROR(__xludf.DUMMYFUNCTION("""COMPUTED_VALUE"""),"Región Sur") -> Región Sur
